[2020-09-16 10:05:19,192] [autoreload.py:612] [autoreload:run_with_reloader] [INFO]- Watching for file changes with StatReloader
[2020-09-16 10:05:58,668] [autoreload.py:612] [autoreload:run_with_reloader] [INFO]- Watching for file changes with StatReloader
[2020-09-16 10:06:22,182] [autoreload.py:236] [autoreload:trigger_reload] [INFO]- /Users/fengdong/PycharmProjects/warn_relaction_interface/flow_predict/warn_relaction_interface/view.py changed, reloading.
[2020-09-16 10:06:22,833] [autoreload.py:612] [autoreload:run_with_reloader] [INFO]- Watching for file changes with StatReloader
[2020-09-16 10:06:35,029] [autoreload.py:612] [autoreload:run_with_reloader] [INFO]- Watching for file changes with StatReloader
[2020-09-16 10:06:39,736] [basehttp.py:157] [basehttp:log_message] [INFO]- "GET / HTTP/1.1" 200 67
[2020-09-16 10:06:40,450] [log.py:230] [log:log_response] [WARNING]- Not Found: /favicon.ico
[2020-09-16 10:06:40,450] [basehttp.py:157] [basehttp:log_message] [WARNING]- "GET /favicon.ico HTTP/1.1" 404 179
[2020-09-16 10:07:03,848] [basehttp.py:157] [basehttp:log_message] [INFO]- "GET /healthcheck.do HTTP/1.1" 200 67
[2020-09-16 10:07:47,198] [basehttp.py:157] [basehttp:log_message] [INFO]- "GET /get_flow HTTP/1.1" 200 67
[2020-09-16 10:09:12,783] [basehttp.py:157] [basehttp:log_message] [INFO]- "GET /get_flow?warn_data_url=127.0.0.1/static/csv/warn_tail_30w.csv HTTP/1.1" 200 67
[2020-09-16 10:12:48,259] [basehttp.py:157] [basehttp:log_message] [INFO]- "GET / HTTP/1.1" 200 67
[2020-09-16 10:13:43,578] [basehttp.py:157] [basehttp:log_message] [INFO]- "GET / HTTP/1.1" 200 67
[2020-09-16 10:29:06,038] [autoreload.py:236] [autoreload:trigger_reload] [INFO]- /Users/fengdong/PycharmProjects/warn_relaction_interface/flow_predict/warn_relaction_interface/core/systen_unit.py changed, reloading.
[2020-09-16 10:29:07,007] [autoreload.py:612] [autoreload:run_with_reloader] [INFO]- Watching for file changes with StatReloader
[2020-09-16 10:30:33,190] [autoreload.py:236] [autoreload:trigger_reload] [INFO]- /Users/fengdong/PycharmProjects/warn_relaction_interface/flow_predict/warn_relaction_interface/view.py changed, reloading.
[2020-09-16 10:30:34,015] [autoreload.py:612] [autoreload:run_with_reloader] [INFO]- Watching for file changes with StatReloader
[2020-09-16 10:31:55,746] [autoreload.py:236] [autoreload:trigger_reload] [INFO]- /Users/fengdong/PycharmProjects/warn_relaction_interface/flow_predict/warn_relaction_interface/view.py changed, reloading.
[2020-09-16 10:31:56,494] [autoreload.py:612] [autoreload:run_with_reloader] [INFO]- Watching for file changes with StatReloader
[2020-09-16 13:56:29,326] [autoreload.py:612] [autoreload:run_with_reloader] [INFO]- Watching for file changes with StatReloader
[2020-09-16 13:56:36,065] [basehttp.py:157] [basehttp:log_message] [INFO]- "GET / HTTP/1.1" 200 67
[2020-09-16 14:42:24,772] [basehttp.py:157] [basehttp:log_message] [INFO]- "GET / HTTP/1.1" 200 67
[2020-09-16 14:43:42,047] [basehttp.py:157] [basehttp:log_message] [INFO]- "GET / HTTP/1.1" 200 67
[2020-09-16 14:44:14,309] [basehttp.py:157] [basehttp:log_message] [INFO]- "GET /healthcheck.do HTTP/1.1" 200 67
[2020-09-16 14:44:25,049] [basehttp.py:157] [basehttp:log_message] [INFO]- "GET /get_flow HTTP/1.1" 200 67
[2020-09-16 14:47:31,584] [basehttp.py:157] [basehttp:log_message] [INFO]- "GET /static/upload/lteFlowOfCity5Min_anshun_guanling.csv HTTP/1.1" 200 45311
[2020-09-16 14:56:06,422] [basehttp.py:157] [basehttp:log_message] [INFO]- "POST / HTTP/1.1" 200 67
[2020-09-16 14:56:38,440] [basehttp.py:157] [basehttp:log_message] [INFO]- "POST /port/healthcheck.do HTTP/1.1" 200 67
[2020-09-16 14:56:39,555] [basehttp.py:157] [basehttp:log_message] [INFO]- "POST /port/healthcheck.do HTTP/1.1" 200 67
[2020-09-16 14:56:40,834] [basehttp.py:157] [basehttp:log_message] [INFO]- "POST /port/healthcheck.do HTTP/1.1" 200 67
[2020-09-16 14:57:39,779] [view.py:78] [view:warn_realtion] [ERROR]- [138007e2b2ae2c82d28b9e409313857b]:Expecting value: line 1 column 1 (char 0)
[2020-09-16 14:57:39,785] [basehttp.py:157] [basehttp:log_message] [INFO]- "POST /get_flow HTTP/1.1" 200 66
[2020-09-16 14:58:13,635] [view.py:78] [view:warn_realtion] [ERROR]- [d0e13b147545a87da6b87a7c2d266fbc]:Expecting value: line 1 column 1 (char 0)
[2020-09-16 14:58:13,638] [basehttp.py:157] [basehttp:log_message] [INFO]- "POST /get_flow HTTP/1.1" 200 66
[2020-09-16 14:58:14,948] [view.py:78] [view:warn_realtion] [ERROR]- [ce9bcd3f95bbc9cfa7355d27e79e5670]:Expecting value: line 1 column 1 (char 0)
[2020-09-16 14:58:14,948] [basehttp.py:157] [basehttp:log_message] [INFO]- "POST /get_flow HTTP/1.1" 200 66
[2020-09-16 14:59:10,422] [basehttp.py:157] [basehttp:log_message] [INFO]- "POST / HTTP/1.1" 200 67
[2020-09-16 15:00:27,569] [view.py:78] [view:warn_realtion] [ERROR]- [250eb3394e2f95ceb38144b7a810d4cf]:Expecting value: line 1 column 1 (char 0)
[2020-09-16 15:00:27,572] [basehttp.py:157] [basehttp:log_message] [INFO]- "POST /get_flow HTTP/1.1" 200 66
[2020-09-16 15:01:02,116] [view.py:78] [view:warn_realtion] [ERROR]- [20048ff364d14572f927560688ff16ab]:Expecting value: line 1 column 1 (char 0)
[2020-09-16 15:01:02,117] [basehttp.py:157] [basehttp:log_message] [INFO]- "POST /get_flow HTTP/1.1" 200 66
[2020-09-16 15:01:03,135] [view.py:78] [view:warn_realtion] [ERROR]- [dd515433cea52770d1b3c03de9d0a671]:Expecting value: line 1 column 1 (char 0)
[2020-09-16 15:01:03,136] [basehttp.py:157] [basehttp:log_message] [INFO]- "POST /get_flow HTTP/1.1" 200 66
[2020-09-16 15:01:32,510] [log.py:230] [log:log_response] [ERROR]- Internal Server Error: /get_resu_process
Traceback (most recent call last):
  File "/Applications/anaconda3/lib/python3.6/site-packages/django/core/handlers/exception.py", line 47, in inner
    response = get_response(request)
  File "/Applications/anaconda3/lib/python3.6/site-packages/django/core/handlers/base.py", line 179, in _get_response
    response = wrapped_callback(request, *callback_args, **callback_kwargs)
  File "/Users/fengdong/PycharmProjects/flowpredict000/flowpredict/warn_relaction_interface/view.py", line 98, in get_resu_process
    req_para = json.loads(req.body)
  File "/Applications/anaconda3/lib/python3.6/json/__init__.py", line 354, in loads
    return _default_decoder.decode(s)
  File "/Applications/anaconda3/lib/python3.6/json/decoder.py", line 339, in decode
    obj, end = self.raw_decode(s, idx=_w(s, 0).end())
  File "/Applications/anaconda3/lib/python3.6/json/decoder.py", line 357, in raw_decode
    raise JSONDecodeError("Expecting value", s, err.value) from None
json.decoder.JSONDecodeError: Expecting value: line 1 column 1 (char 0)
[2020-09-16 15:01:32,518] [basehttp.py:157] [basehttp:log_message] [ERROR]- "POST /get_resu_process HTTP/1.1" 500 145
[2020-09-16 15:01:58,583] [log.py:230] [log:log_response] [ERROR]- Internal Server Error: /get_resu_process
Traceback (most recent call last):
  File "/Applications/anaconda3/lib/python3.6/site-packages/django/core/handlers/exception.py", line 47, in inner
    response = get_response(request)
  File "/Applications/anaconda3/lib/python3.6/site-packages/django/core/handlers/base.py", line 179, in _get_response
    response = wrapped_callback(request, *callback_args, **callback_kwargs)
  File "/Users/fengdong/PycharmProjects/flowpredict000/flowpredict/warn_relaction_interface/view.py", line 98, in get_resu_process
    req_para = json.loads(req.body)
  File "/Applications/anaconda3/lib/python3.6/json/__init__.py", line 354, in loads
    return _default_decoder.decode(s)
  File "/Applications/anaconda3/lib/python3.6/json/decoder.py", line 339, in decode
    obj, end = self.raw_decode(s, idx=_w(s, 0).end())
  File "/Applications/anaconda3/lib/python3.6/json/decoder.py", line 357, in raw_decode
    raise JSONDecodeError("Expecting value", s, err.value) from None
json.decoder.JSONDecodeError: Expecting value: line 1 column 1 (char 0)
[2020-09-16 15:01:58,584] [basehttp.py:157] [basehttp:log_message] [ERROR]- "POST /get_resu_process HTTP/1.1" 500 145
[2020-09-16 15:02:15,704] [log.py:230] [log:log_response] [ERROR]- Internal Server Error: /get_resu_process
Traceback (most recent call last):
  File "/Applications/anaconda3/lib/python3.6/site-packages/django/core/handlers/exception.py", line 47, in inner
    response = get_response(request)
  File "/Applications/anaconda3/lib/python3.6/site-packages/django/core/handlers/base.py", line 179, in _get_response
    response = wrapped_callback(request, *callback_args, **callback_kwargs)
  File "/Users/fengdong/PycharmProjects/flowpredict000/flowpredict/warn_relaction_interface/view.py", line 98, in get_resu_process
    req_para = json.loads(req.body)
  File "/Applications/anaconda3/lib/python3.6/json/__init__.py", line 354, in loads
    return _default_decoder.decode(s)
  File "/Applications/anaconda3/lib/python3.6/json/decoder.py", line 339, in decode
    obj, end = self.raw_decode(s, idx=_w(s, 0).end())
  File "/Applications/anaconda3/lib/python3.6/json/decoder.py", line 357, in raw_decode
    raise JSONDecodeError("Expecting value", s, err.value) from None
json.decoder.JSONDecodeError: Expecting value: line 1 column 1 (char 0)
[2020-09-16 15:02:15,705] [basehttp.py:157] [basehttp:log_message] [ERROR]- "POST /get_resu_process HTTP/1.1" 500 145
[2020-09-16 15:02:22,690] [log.py:230] [log:log_response] [ERROR]- Internal Server Error: /get_resu_process
Traceback (most recent call last):
  File "/Applications/anaconda3/lib/python3.6/site-packages/django/core/handlers/exception.py", line 47, in inner
    response = get_response(request)
  File "/Applications/anaconda3/lib/python3.6/site-packages/django/core/handlers/base.py", line 179, in _get_response
    response = wrapped_callback(request, *callback_args, **callback_kwargs)
  File "/Users/fengdong/PycharmProjects/flowpredict000/flowpredict/warn_relaction_interface/view.py", line 98, in get_resu_process
    req_para = json.loads(req.body)
  File "/Applications/anaconda3/lib/python3.6/json/__init__.py", line 354, in loads
    return _default_decoder.decode(s)
  File "/Applications/anaconda3/lib/python3.6/json/decoder.py", line 339, in decode
    obj, end = self.raw_decode(s, idx=_w(s, 0).end())
  File "/Applications/anaconda3/lib/python3.6/json/decoder.py", line 357, in raw_decode
    raise JSONDecodeError("Expecting value", s, err.value) from None
json.decoder.JSONDecodeError: Expecting value: line 1 column 1 (char 0)
[2020-09-16 15:02:22,691] [basehttp.py:157] [basehttp:log_message] [ERROR]- "POST /get_resu_process HTTP/1.1" 500 145
[2020-09-16 15:04:02,924] [basehttp.py:157] [basehttp:log_message] [INFO]- "POST /upload_file HTTP/1.1" 200 128
[2020-09-16 15:05:44,999] [basehttp.py:157] [basehttp:log_message] [INFO]- "POST /upload_file HTTP/1.1" 200 128
[2020-09-16 15:05:48,762] [basehttp.py:157] [basehttp:log_message] [INFO]- "POST /upload_file HTTP/1.1" 200 128
[2020-09-16 15:06:30,171] [basehttp.py:157] [basehttp:log_message] [INFO]- "POST /healthcheck.do HTTP/1.1" 200 67
[2020-09-16 15:06:45,142] [log.py:230] [log:log_response] [ERROR]- Internal Server Error: /get_resu_process
Traceback (most recent call last):
  File "/Applications/anaconda3/lib/python3.6/site-packages/django/core/handlers/exception.py", line 47, in inner
    response = get_response(request)
  File "/Applications/anaconda3/lib/python3.6/site-packages/django/core/handlers/base.py", line 179, in _get_response
    response = wrapped_callback(request, *callback_args, **callback_kwargs)
  File "/Users/fengdong/PycharmProjects/flowpredict000/flowpredict/warn_relaction_interface/view.py", line 98, in get_resu_process
    req_para = json.loads(req.body)
  File "/Applications/anaconda3/lib/python3.6/json/__init__.py", line 354, in loads
    return _default_decoder.decode(s)
  File "/Applications/anaconda3/lib/python3.6/json/decoder.py", line 339, in decode
    obj, end = self.raw_decode(s, idx=_w(s, 0).end())
  File "/Applications/anaconda3/lib/python3.6/json/decoder.py", line 357, in raw_decode
    raise JSONDecodeError("Expecting value", s, err.value) from None
json.decoder.JSONDecodeError: Expecting value: line 1 column 1 (char 0)
[2020-09-16 15:06:45,144] [basehttp.py:157] [basehttp:log_message] [ERROR]- "POST /get_resu_process HTTP/1.1" 500 145
[2020-09-16 15:11:50,772] [autoreload.py:612] [autoreload:run_with_reloader] [INFO]- Watching for file changes with StatReloader
[2020-09-16 15:12:06,743] [basehttp.py:157] [basehttp:log_message] [INFO]- "GET / HTTP/1.1" 200 67
[2020-09-16 15:12:34,770] [basehttp.py:157] [basehttp:log_message] [INFO]- "GET / HTTP/1.1" 200 67
[2020-09-16 15:12:49,539] [basehttp.py:157] [basehttp:log_message] [INFO]- "POST / HTTP/1.1" 200 67
[2020-09-16 15:13:31,385] [view.py:78] [view:warn_realtion] [ERROR]- [c1b2fdea7b9379d8e93374bbbfa65803]:Expecting value: line 1 column 1 (char 0)
[2020-09-16 15:13:31,392] [basehttp.py:157] [basehttp:log_message] [INFO]- "POST /get_flow HTTP/1.1" 200 66
[2020-09-16 15:14:36,212] [basehttp.py:157] [basehttp:log_message] [INFO]- "POST /upload_file HTTP/1.1" 200 128
[2020-09-16 15:14:50,521] [basehttp.py:157] [basehttp:log_message] [INFO]- "POST /upload_file HTTP/1.1" 200 128
[2020-09-16 15:14:51,468] [basehttp.py:157] [basehttp:log_message] [INFO]- "POST /upload_file HTTP/1.1" 200 128
[2020-09-16 15:17:45,061] [basehttp.py:157] [basehttp:log_message] [INFO]- "POST / HTTP/1.1" 200 67
[2020-09-16 15:26:49,313] [autoreload.py:612] [autoreload:run_with_reloader] [INFO]- Watching for file changes with StatReloader
[2020-09-16 15:27:38,640] [view.py:78] [view:warn_realtion] [ERROR]- [e1e6e68afdd1e448802a65983ce53b35]:Expecting value: line 1 column 1 (char 0)
[2020-09-16 15:27:38,642] [basehttp.py:157] [basehttp:log_message] [INFO]- "POST /get_flow HTTP/1.1" 200 66
[2020-09-16 15:27:48,435] [view.py:78] [view:warn_realtion] [ERROR]- [5aee528b90c1d369a5efac777f72b464]:Expecting value: line 1 column 1 (char 0)
[2020-09-16 15:27:48,435] [basehttp.py:157] [basehttp:log_message] [INFO]- "POST /get_flow HTTP/1.1" 200 66
[2020-09-16 15:27:57,525] [view.py:78] [view:warn_realtion] [ERROR]- [a945393e228d0241f9497bd327008868]:Expecting value: line 1 column 1 (char 0)
[2020-09-16 15:27:57,532] [basehttp.py:157] [basehttp:log_message] [INFO]- "POST /get_flow HTTP/1.1" 200 66
[2020-09-16 15:29:09,949] [view.py:78] [view:warn_realtion] [ERROR]- [dcf1e55ed481316ff0f899d22a87c114]:Expecting value: line 1 column 1 (char 0)
[2020-09-16 15:29:09,952] [basehttp.py:157] [basehttp:log_message] [INFO]- "POST /get_flow HTTP/1.1" 200 66
[2020-09-16 15:30:01,251] [view.py:78] [view:warn_realtion] [ERROR]- [d26299cdebb3fe94f532b80ef3a96a52]:Expecting value: line 1 column 1 (char 0)
[2020-09-16 15:30:01,252] [basehttp.py:157] [basehttp:log_message] [INFO]- "POST /get_flow HTTP/1.1" 200 66
[2020-09-16 15:30:22,585] [view.py:78] [view:warn_realtion] [ERROR]- [71462d3021c45454fff3a15ad7755519]:Expecting value: line 1 column 1 (char 0)
[2020-09-16 15:30:22,585] [basehttp.py:157] [basehttp:log_message] [INFO]- "POST /get_flow HTTP/1.1" 200 66
[2020-09-16 15:30:23,941] [view.py:78] [view:warn_realtion] [ERROR]- [2ecf1b7ff1cb2890ef7f5cb8cbd741c8]:Expecting value: line 1 column 1 (char 0)
[2020-09-16 15:30:23,942] [basehttp.py:157] [basehttp:log_message] [INFO]- "POST /get_flow HTTP/1.1" 200 66
[2020-09-16 15:30:24,765] [view.py:78] [view:warn_realtion] [ERROR]- [a63771ae62681cdf70904d7bde1bbdad]:Expecting value: line 1 column 1 (char 0)
[2020-09-16 15:30:24,766] [basehttp.py:157] [basehttp:log_message] [INFO]- "POST /get_flow HTTP/1.1" 200 66
[2020-09-16 15:30:25,373] [view.py:78] [view:warn_realtion] [ERROR]- [8fe50d7be4b437d5f85c239f57ff92ea]:Expecting value: line 1 column 1 (char 0)
[2020-09-16 15:30:25,373] [basehttp.py:157] [basehttp:log_message] [INFO]- "POST /get_flow HTTP/1.1" 200 66
[2020-09-16 15:30:25,534] [view.py:78] [view:warn_realtion] [ERROR]- [fadd6fa62896b011e18f240bca3c5561]:Expecting value: line 1 column 1 (char 0)
[2020-09-16 15:30:25,535] [basehttp.py:157] [basehttp:log_message] [INFO]- "POST /get_flow HTTP/1.1" 200 66
[2020-09-16 15:30:25,670] [view.py:78] [view:warn_realtion] [ERROR]- [2094c1d0b3e9afc9732cefcff7018c3b]:Expecting value: line 1 column 1 (char 0)
[2020-09-16 15:30:25,671] [basehttp.py:157] [basehttp:log_message] [INFO]- "POST /get_flow HTTP/1.1" 200 66
[2020-09-16 15:30:25,809] [view.py:78] [view:warn_realtion] [ERROR]- [83b297cdef6a26dfe6176c07cbaa22c3]:Expecting value: line 1 column 1 (char 0)
[2020-09-16 15:30:25,809] [basehttp.py:157] [basehttp:log_message] [INFO]- "POST /get_flow HTTP/1.1" 200 66
[2020-09-16 15:30:42,320] [autoreload.py:236] [autoreload:trigger_reload] [INFO]- /Users/fengdong/PycharmProjects/flowpredict000/flowpredict/warn_relaction_interface/view.py changed, reloading.
[2020-09-16 15:30:43,316] [autoreload.py:612] [autoreload:run_with_reloader] [INFO]- Watching for file changes with StatReloader
[2020-09-16 15:30:53,413] [view.py:78] [view:warn_realtion] [ERROR]- [a6999dde9404c7020031d6589268eba1]:Expecting value: line 1 column 1 (char 0)
[2020-09-16 15:30:53,416] [basehttp.py:157] [basehttp:log_message] [INFO]- "POST /get_flow HTTP/1.1" 200 66
[2020-09-16 15:31:04,303] [view.py:78] [view:warn_realtion] [ERROR]- [ce84a86f025d9a62c60f6d7d2ce8a5a3]:Expecting value: line 1 column 1 (char 0)
[2020-09-16 15:31:04,304] [basehttp.py:157] [basehttp:log_message] [INFO]- "POST /get_flow HTTP/1.1" 200 66
[2020-09-16 15:31:04,334] [autoreload.py:236] [autoreload:trigger_reload] [INFO]- /Users/fengdong/PycharmProjects/flowpredict000/flowpredict/warn_relaction_interface/view.py changed, reloading.
[2020-09-16 15:31:05,106] [autoreload.py:612] [autoreload:run_with_reloader] [INFO]- Watching for file changes with StatReloader
[2020-09-16 15:31:19,693] [autoreload.py:236] [autoreload:trigger_reload] [INFO]- /Users/fengdong/PycharmProjects/flowpredict000/flowpredict/warn_relaction_interface/view.py changed, reloading.
[2020-09-16 15:31:20,584] [autoreload.py:612] [autoreload:run_with_reloader] [INFO]- Watching for file changes with StatReloader
[2020-09-16 15:31:26,178] [view.py:79] [view:warn_realtion] [ERROR]- [e1169aa25663e782dbea4ba03f51b55d]:Expecting value: line 1 column 1 (char 0)
[2020-09-16 15:31:26,179] [basehttp.py:157] [basehttp:log_message] [INFO]- "POST /get_flow HTTP/1.1" 200 66
[2020-09-16 15:31:36,540] [autoreload.py:236] [autoreload:trigger_reload] [INFO]- /Users/fengdong/PycharmProjects/flowpredict000/flowpredict/warn_relaction_interface/view.py changed, reloading.
[2020-09-16 15:31:37,434] [autoreload.py:612] [autoreload:run_with_reloader] [INFO]- Watching for file changes with StatReloader
[2020-09-16 15:31:44,020] [view.py:79] [view:warn_realtion] [ERROR]- [f60669a554a11f16498f959d1e00369d]:Expecting value: line 1 column 1 (char 0)
[2020-09-16 15:31:44,023] [basehttp.py:157] [basehttp:log_message] [INFO]- "POST /get_flow HTTP/1.1" 200 66
[2020-09-16 15:32:28,691] [autoreload.py:236] [autoreload:trigger_reload] [INFO]- /Users/fengdong/PycharmProjects/flowpredict000/flowpredict/warn_relaction_interface/view.py changed, reloading.
[2020-09-16 15:32:29,648] [autoreload.py:612] [autoreload:run_with_reloader] [INFO]- Watching for file changes with StatReloader
[2020-09-16 15:32:33,550] [view.py:79] [view:warn_realtion] [ERROR]- [d07aa782c93485e2c5128a1b00676f39]:Expecting value: line 1 column 1 (char 0)
[2020-09-16 15:32:33,551] [basehttp.py:157] [basehttp:log_message] [INFO]- "POST /get_flow HTTP/1.1" 200 66
[2020-09-16 15:32:35,633] [view.py:79] [view:warn_realtion] [ERROR]- [0335e9476932a91686ca6978e77b164d]:Expecting value: line 1 column 1 (char 0)
[2020-09-16 15:32:35,633] [basehttp.py:157] [basehttp:log_message] [INFO]- "POST /get_flow HTTP/1.1" 200 66
[2020-09-16 15:32:36,981] [view.py:79] [view:warn_realtion] [ERROR]- [7229fd0c81a03a2bf10eccab30a75edf]:Expecting value: line 1 column 1 (char 0)
[2020-09-16 15:32:36,982] [basehttp.py:157] [basehttp:log_message] [INFO]- "POST /get_flow HTTP/1.1" 200 66
[2020-09-16 15:32:37,452] [view.py:79] [view:warn_realtion] [ERROR]- [4453c65159fbd6d862593b147143bef5]:Expecting value: line 1 column 1 (char 0)
[2020-09-16 15:32:37,453] [basehttp.py:157] [basehttp:log_message] [INFO]- "POST /get_flow HTTP/1.1" 200 66
[2020-09-16 15:32:37,613] [view.py:79] [view:warn_realtion] [ERROR]- [2c08163d9b4da050d22463470f6e8807]:Expecting value: line 1 column 1 (char 0)
[2020-09-16 15:32:37,613] [basehttp.py:157] [basehttp:log_message] [INFO]- "POST /get_flow HTTP/1.1" 200 66
[2020-09-16 15:32:37,761] [view.py:79] [view:warn_realtion] [ERROR]- [1d653341a07405be45bb2819d566ef9b]:Expecting value: line 1 column 1 (char 0)
[2020-09-16 15:32:37,761] [basehttp.py:157] [basehttp:log_message] [INFO]- "POST /get_flow HTTP/1.1" 200 66
[2020-09-16 15:32:47,976] [view.py:79] [view:warn_realtion] [ERROR]- [204bac969ce842d80bfad8dc893631e4]:Expecting value: line 1 column 1 (char 0)
[2020-09-16 15:32:47,976] [basehttp.py:157] [basehttp:log_message] [INFO]- "POST /get_flow HTTP/1.1" 200 66
[2020-09-16 15:32:48,486] [autoreload.py:236] [autoreload:trigger_reload] [INFO]- /Users/fengdong/PycharmProjects/flowpredict000/flowpredict/warn_relaction_interface/view.py changed, reloading.
[2020-09-16 15:32:49,412] [autoreload.py:612] [autoreload:run_with_reloader] [INFO]- Watching for file changes with StatReloader
[2020-09-16 15:32:56,927] [view.py:80] [view:warn_realtion] [ERROR]- [1b3ebe12790aff7b2ab7461290d99f07]:Expecting value: line 1 column 1 (char 0)
[2020-09-16 15:32:56,928] [basehttp.py:157] [basehttp:log_message] [INFO]- "POST /get_flow HTTP/1.1" 200 66
[2020-09-16 15:32:59,538] [view.py:80] [view:warn_realtion] [ERROR]- [57fc8db334292401644c46de3d23f862]:Expecting value: line 1 column 1 (char 0)
[2020-09-16 15:32:59,538] [basehttp.py:157] [basehttp:log_message] [INFO]- "POST /get_flow HTTP/1.1" 200 66
[2020-09-16 15:33:00,451] [view.py:80] [view:warn_realtion] [ERROR]- [df2673fc86d0aad54fb72d1b93e2d1cf]:Expecting value: line 1 column 1 (char 0)
[2020-09-16 15:33:00,452] [basehttp.py:157] [basehttp:log_message] [INFO]- "POST /get_flow HTTP/1.1" 200 66
[2020-09-16 15:33:01,472] [view.py:80] [view:warn_realtion] [ERROR]- [ea6caad9c1c5d74e3c85baee2ca7805b]:Expecting value: line 1 column 1 (char 0)
[2020-09-16 15:33:01,472] [basehttp.py:157] [basehttp:log_message] [INFO]- "POST /get_flow HTTP/1.1" 200 66
[2020-09-16 15:33:16,588] [view.py:80] [view:warn_realtion] [ERROR]- [80fce2dc384d945c54b503db5aaa92de]:Expecting value: line 1 column 1 (char 0)
[2020-09-16 15:33:16,588] [basehttp.py:157] [basehttp:log_message] [INFO]- "POST /get_flow HTTP/1.1" 200 66
[2020-09-16 15:33:16,672] [autoreload.py:236] [autoreload:trigger_reload] [INFO]- /Users/fengdong/PycharmProjects/flowpredict000/flowpredict/warn_relaction_interface/view.py changed, reloading.
[2020-09-16 15:33:17,594] [autoreload.py:612] [autoreload:run_with_reloader] [INFO]- Watching for file changes with StatReloader
[2020-09-16 15:33:22,696] [view.py:80] [view:warn_realtion] [ERROR]- [88fe72559f3ddd6b14a38b8aab9beca8]:Expecting value: line 1 column 1 (char 0)
[2020-09-16 15:33:22,698] [basehttp.py:157] [basehttp:log_message] [INFO]- "POST /get_flow HTTP/1.1" 200 66
[2020-09-16 15:34:34,657] [view.py:80] [view:warn_realtion] [ERROR]- [62fe60ad7408a8075d44f538a9ce0265]:Expecting value: line 1 column 1 (char 0)
[2020-09-16 15:34:34,658] [basehttp.py:157] [basehttp:log_message] [INFO]- "POST /get_flow HTTP/1.1" 200 66
[2020-09-16 15:34:36,488] [view.py:80] [view:warn_realtion] [ERROR]- [9b7e7ef08b0a74d917cd4b26647ac7be]:Expecting value: line 1 column 1 (char 0)
[2020-09-16 15:34:36,489] [basehttp.py:157] [basehttp:log_message] [INFO]- "POST /get_flow HTTP/1.1" 200 66
[2020-09-16 15:34:49,173] [view.py:80] [view:warn_realtion] [ERROR]- [f0c2f01a1f59e51074e9d4bcf56a1e77]:Expecting value: line 1 column 1 (char 0)
[2020-09-16 15:34:49,173] [basehttp.py:157] [basehttp:log_message] [INFO]- "POST /get_flow HTTP/1.1" 200 66
[2020-09-16 15:36:05,712] [view.py:80] [view:warn_realtion] [ERROR]- [ecc077aea42024de75781d73bcc68fcd]:Expecting value: line 1 column 1 (char 0)
[2020-09-16 15:36:05,713] [basehttp.py:157] [basehttp:log_message] [INFO]- "POST /get_flow HTTP/1.1" 200 66
[2020-09-16 15:36:05,921] [autoreload.py:236] [autoreload:trigger_reload] [INFO]- /Users/fengdong/PycharmProjects/flowpredict000/flowpredict/warn_relaction_interface/view.py changed, reloading.
[2020-09-16 15:36:06,899] [autoreload.py:612] [autoreload:run_with_reloader] [INFO]- Watching for file changes with StatReloader
[2020-09-16 15:36:11,818] [view.py:80] [view:warn_realtion] [ERROR]- [4098ade228cccbe81295d7d1e80fbd99]:Expecting value: line 1 column 1 (char 0)
[2020-09-16 15:36:11,819] [basehttp.py:157] [basehttp:log_message] [INFO]- "POST /get_flow HTTP/1.1" 200 66
[2020-09-16 15:36:13,441] [view.py:80] [view:warn_realtion] [ERROR]- [ee34e4b8cbcc0a582dcdbad5170b823b]:Expecting value: line 1 column 1 (char 0)
[2020-09-16 15:36:13,442] [basehttp.py:157] [basehttp:log_message] [INFO]- "POST /get_flow HTTP/1.1" 200 66
[2020-09-16 15:36:33,167] [autoreload.py:236] [autoreload:trigger_reload] [INFO]- /Users/fengdong/PycharmProjects/flowpredict000/flowpredict/warn_relaction_interface/view.py changed, reloading.
[2020-09-16 15:36:33,920] [autoreload.py:612] [autoreload:run_with_reloader] [INFO]- Watching for file changes with StatReloader
[2020-09-16 15:36:35,736] [view.py:80] [view:warn_realtion] [ERROR]- [be6782ec233325e997db3d9737515709]:Expecting value: line 1 column 1 (char 0)
[2020-09-16 15:36:35,737] [basehttp.py:157] [basehttp:log_message] [INFO]- "POST /get_flow HTTP/1.1" 200 66
[2020-09-16 15:36:37,499] [view.py:80] [view:warn_realtion] [ERROR]- [8c01c280a2db7370e38368046b0185d7]:Expecting value: line 1 column 1 (char 0)
[2020-09-16 15:36:37,499] [basehttp.py:157] [basehttp:log_message] [INFO]- "POST /get_flow HTTP/1.1" 200 66
[2020-09-16 15:36:38,386] [view.py:80] [view:warn_realtion] [ERROR]- [fe7932f3ebbc56a95a7a6702e55930f7]:Expecting value: line 1 column 1 (char 0)
[2020-09-16 15:36:38,386] [basehttp.py:157] [basehttp:log_message] [INFO]- "POST /get_flow HTTP/1.1" 200 66
[2020-09-16 15:44:14,285] [autoreload.py:612] [autoreload:run_with_reloader] [INFO]- Watching for file changes with StatReloader
[2020-09-16 15:44:37,257] [basehttp.py:157] [basehttp:log_message] [INFO]- "POST / HTTP/1.1" 200 67
[2020-09-16 15:45:21,473] [basehttp.py:157] [basehttp:log_message] [INFO]- "POST / HTTP/1.1" 200 67
[2020-09-16 15:45:45,033] [basehttp.py:157] [basehttp:log_message] [INFO]- "POST / HTTP/1.1" 200 67
[2020-09-16 15:45:54,459] [basehttp.py:157] [basehttp:log_message] [INFO]- "POST / HTTP/1.1" 200 67
[2020-09-16 15:46:12,630] [view.py:80] [view:warn_realtion] [ERROR]- [5371662f70d94c1aa4629fe26095e3b2]:Expecting value: line 1 column 1 (char 0)
[2020-09-16 15:46:12,631] [basehttp.py:157] [basehttp:log_message] [INFO]- "POST /get_flow HTTP/1.1" 200 66
[2020-09-16 15:46:48,240] [view.py:80] [view:warn_realtion] [ERROR]- [3e7e5371e78f125310d85e27796d5599]:Expecting value: line 1 column 1 (char 0)
[2020-09-16 15:46:48,241] [basehttp.py:157] [basehttp:log_message] [INFO]- "POST /get_flow HTTP/1.1" 200 66
[2020-09-16 15:47:12,254] [view.py:80] [view:warn_realtion] [ERROR]- [d338ff45726e8311533b39b40eaffa3f]:Expecting value: line 1 column 1 (char 0)
[2020-09-16 15:47:12,254] [basehttp.py:157] [basehttp:log_message] [INFO]- "POST /get_flow HTTP/1.1" 200 66
[2020-09-16 15:50:25,097] [log.py:230] [log:log_response] [ERROR]- Internal Server Error: /get_resu_process
Traceback (most recent call last):
  File "/Applications/anaconda3/lib/python3.6/site-packages/django/core/handlers/exception.py", line 47, in inner
    response = get_response(request)
  File "/Applications/anaconda3/lib/python3.6/site-packages/django/core/handlers/base.py", line 179, in _get_response
    response = wrapped_callback(request, *callback_args, **callback_kwargs)
  File "/Users/fengdong/PycharmProjects/flowpredict000/flowpredict/warn_relaction_interface/view.py", line 100, in get_resu_process
    req_para = json.loads(req.body)
  File "/Applications/anaconda3/lib/python3.6/json/__init__.py", line 354, in loads
    return _default_decoder.decode(s)
  File "/Applications/anaconda3/lib/python3.6/json/decoder.py", line 339, in decode
    obj, end = self.raw_decode(s, idx=_w(s, 0).end())
  File "/Applications/anaconda3/lib/python3.6/json/decoder.py", line 357, in raw_decode
    raise JSONDecodeError("Expecting value", s, err.value) from None
json.decoder.JSONDecodeError: Expecting value: line 1 column 1 (char 0)
[2020-09-16 15:50:25,103] [basehttp.py:157] [basehttp:log_message] [ERROR]- "POST /get_resu_process HTTP/1.1" 500 145
[2020-09-16 15:50:50,983] [log.py:230] [log:log_response] [ERROR]- Internal Server Error: /get_resu_process
Traceback (most recent call last):
  File "/Applications/anaconda3/lib/python3.6/site-packages/django/core/handlers/exception.py", line 47, in inner
    response = get_response(request)
  File "/Applications/anaconda3/lib/python3.6/site-packages/django/core/handlers/base.py", line 179, in _get_response
    response = wrapped_callback(request, *callback_args, **callback_kwargs)
  File "/Users/fengdong/PycharmProjects/flowpredict000/flowpredict/warn_relaction_interface/view.py", line 100, in get_resu_process
    req_para = json.loads(req.body)
  File "/Applications/anaconda3/lib/python3.6/json/__init__.py", line 354, in loads
    return _default_decoder.decode(s)
  File "/Applications/anaconda3/lib/python3.6/json/decoder.py", line 339, in decode
    obj, end = self.raw_decode(s, idx=_w(s, 0).end())
  File "/Applications/anaconda3/lib/python3.6/json/decoder.py", line 357, in raw_decode
    raise JSONDecodeError("Expecting value", s, err.value) from None
json.decoder.JSONDecodeError: Expecting value: line 1 column 1 (char 0)
[2020-09-16 15:50:50,984] [basehttp.py:157] [basehttp:log_message] [ERROR]- "POST /get_resu_process HTTP/1.1" 500 145
[2020-09-16 15:51:01,639] [log.py:230] [log:log_response] [ERROR]- Internal Server Error: /get_resu_process
Traceback (most recent call last):
  File "/Applications/anaconda3/lib/python3.6/site-packages/django/core/handlers/exception.py", line 47, in inner
    response = get_response(request)
  File "/Applications/anaconda3/lib/python3.6/site-packages/django/core/handlers/base.py", line 179, in _get_response
    response = wrapped_callback(request, *callback_args, **callback_kwargs)
  File "/Users/fengdong/PycharmProjects/flowpredict000/flowpredict/warn_relaction_interface/view.py", line 100, in get_resu_process
    req_para = json.loads(req.body)
  File "/Applications/anaconda3/lib/python3.6/json/__init__.py", line 354, in loads
    return _default_decoder.decode(s)
  File "/Applications/anaconda3/lib/python3.6/json/decoder.py", line 339, in decode
    obj, end = self.raw_decode(s, idx=_w(s, 0).end())
  File "/Applications/anaconda3/lib/python3.6/json/decoder.py", line 357, in raw_decode
    raise JSONDecodeError("Expecting value", s, err.value) from None
json.decoder.JSONDecodeError: Expecting value: line 1 column 1 (char 0)
[2020-09-16 15:51:01,640] [basehttp.py:157] [basehttp:log_message] [ERROR]- "POST /get_resu_process HTTP/1.1" 500 145
[2020-09-16 15:51:42,446] [autoreload.py:236] [autoreload:trigger_reload] [INFO]- /Users/fengdong/PycharmProjects/flowpredict000/flowpredict/warn_relaction_interface/view.py changed, reloading.
[2020-09-16 15:51:43,426] [autoreload.py:612] [autoreload:run_with_reloader] [INFO]- Watching for file changes with StatReloader
[2020-09-16 15:51:47,309] [log.py:230] [log:log_response] [ERROR]- Internal Server Error: /get_resu_process
Traceback (most recent call last):
  File "/Applications/anaconda3/lib/python3.6/site-packages/django/core/handlers/exception.py", line 47, in inner
    response = get_response(request)
  File "/Applications/anaconda3/lib/python3.6/site-packages/django/core/handlers/base.py", line 179, in _get_response
    response = wrapped_callback(request, *callback_args, **callback_kwargs)
  File "/Users/fengdong/PycharmProjects/flowpredict000/flowpredict/warn_relaction_interface/view.py", line 101, in get_resu_process
    print(str(req.bod))
AttributeError: 'WSGIRequest' object has no attribute 'bod'
[2020-09-16 15:51:47,312] [basehttp.py:157] [basehttp:log_message] [ERROR]- "POST /get_resu_process HTTP/1.1" 500 145
[2020-09-16 15:52:19,044] [autoreload.py:236] [autoreload:trigger_reload] [INFO]- /Users/fengdong/PycharmProjects/flowpredict000/flowpredict/warn_relaction_interface/view.py changed, reloading.
[2020-09-16 15:52:19,853] [autoreload.py:612] [autoreload:run_with_reloader] [INFO]- Watching for file changes with StatReloader
[2020-09-16 15:53:02,476] [log.py:230] [log:log_response] [ERROR]- Internal Server Error: /get_resu_process
Traceback (most recent call last):
  File "/Applications/anaconda3/lib/python3.6/site-packages/django/core/handlers/exception.py", line 47, in inner
    response = get_response(request)
  File "/Applications/anaconda3/lib/python3.6/site-packages/django/core/handlers/base.py", line 179, in _get_response
    response = wrapped_callback(request, *callback_args, **callback_kwargs)
  File "/Users/fengdong/PycharmProjects/flowpredict000/flowpredict/warn_relaction_interface/view.py", line 102, in get_resu_process
    req_para = json.loads(req.body)
  File "/Applications/anaconda3/lib/python3.6/json/__init__.py", line 354, in loads
    return _default_decoder.decode(s)
  File "/Applications/anaconda3/lib/python3.6/json/decoder.py", line 339, in decode
    obj, end = self.raw_decode(s, idx=_w(s, 0).end())
  File "/Applications/anaconda3/lib/python3.6/json/decoder.py", line 357, in raw_decode
    raise JSONDecodeError("Expecting value", s, err.value) from None
json.decoder.JSONDecodeError: Expecting value: line 1 column 1 (char 0)
[2020-09-16 15:53:02,482] [basehttp.py:157] [basehttp:log_message] [ERROR]- "POST /get_resu_process HTTP/1.1" 500 145
[2020-09-16 15:53:47,840] [autoreload.py:236] [autoreload:trigger_reload] [INFO]- /Users/fengdong/PycharmProjects/flowpredict000/flowpredict/warn_relaction_interface/view.py changed, reloading.
[2020-09-16 15:53:48,713] [autoreload.py:612] [autoreload:run_with_reloader] [INFO]- Watching for file changes with StatReloader
[2020-09-16 15:53:55,146] [log.py:230] [log:log_response] [ERROR]- Internal Server Error: /get_resu_process
Traceback (most recent call last):
  File "/Applications/anaconda3/lib/python3.6/site-packages/django/core/handlers/exception.py", line 47, in inner
    response = get_response(request)
  File "/Applications/anaconda3/lib/python3.6/site-packages/django/core/handlers/base.py", line 179, in _get_response
    response = wrapped_callback(request, *callback_args, **callback_kwargs)
  File "/Users/fengdong/PycharmProjects/flowpredict000/flowpredict/warn_relaction_interface/view.py", line 102, in get_resu_process
    req_para = json.loads(req.body)
  File "/Applications/anaconda3/lib/python3.6/json/__init__.py", line 354, in loads
    return _default_decoder.decode(s)
  File "/Applications/anaconda3/lib/python3.6/json/decoder.py", line 339, in decode
    obj, end = self.raw_decode(s, idx=_w(s, 0).end())
  File "/Applications/anaconda3/lib/python3.6/json/decoder.py", line 357, in raw_decode
    raise JSONDecodeError("Expecting value", s, err.value) from None
json.decoder.JSONDecodeError: Expecting value: line 1 column 1 (char 0)
[2020-09-16 15:53:55,148] [basehttp.py:157] [basehttp:log_message] [ERROR]- "POST /get_resu_process HTTP/1.1" 500 145
[2020-09-16 15:54:52,240] [autoreload.py:236] [autoreload:trigger_reload] [INFO]- /Users/fengdong/PycharmProjects/flowpredict000/flowpredict/warn_relaction_interface/view.py changed, reloading.
[2020-09-16 15:54:52,876] [autoreload.py:612] [autoreload:run_with_reloader] [INFO]- Watching for file changes with StatReloader
[2020-09-16 15:55:06,591] [log.py:230] [log:log_response] [ERROR]- Internal Server Error: /get_resu_process
Traceback (most recent call last):
  File "/Applications/anaconda3/lib/python3.6/site-packages/django/core/handlers/exception.py", line 47, in inner
    response = get_response(request)
  File "/Applications/anaconda3/lib/python3.6/site-packages/django/core/handlers/base.py", line 179, in _get_response
    response = wrapped_callback(request, *callback_args, **callback_kwargs)
  File "/Users/fengdong/PycharmProjects/flowpredict000/flowpredict/warn_relaction_interface/view.py", line 101, in get_resu_process
    req_para = json.loads(req.body)
  File "/Applications/anaconda3/lib/python3.6/json/__init__.py", line 354, in loads
    return _default_decoder.decode(s)
  File "/Applications/anaconda3/lib/python3.6/json/decoder.py", line 339, in decode
    obj, end = self.raw_decode(s, idx=_w(s, 0).end())
  File "/Applications/anaconda3/lib/python3.6/json/decoder.py", line 357, in raw_decode
    raise JSONDecodeError("Expecting value", s, err.value) from None
json.decoder.JSONDecodeError: Expecting value: line 1 column 1 (char 0)
[2020-09-16 15:55:06,596] [basehttp.py:157] [basehttp:log_message] [ERROR]- "POST /get_resu_process HTTP/1.1" 500 145
[2020-09-16 15:59:18,547] [autoreload.py:236] [autoreload:trigger_reload] [INFO]- /Users/fengdong/PycharmProjects/flowpredict000/flowpredict/warn_relaction_interface/view.py changed, reloading.
[2020-09-16 15:59:19,206] [autoreload.py:612] [autoreload:run_with_reloader] [INFO]- Watching for file changes with StatReloader
[2020-09-16 15:59:39,528] [log.py:230] [log:log_response] [ERROR]- Internal Server Error: /get_resu_process
Traceback (most recent call last):
  File "/Applications/anaconda3/lib/python3.6/site-packages/django/core/handlers/exception.py", line 47, in inner
    response = get_response(request)
  File "/Applications/anaconda3/lib/python3.6/site-packages/django/core/handlers/base.py", line 179, in _get_response
    response = wrapped_callback(request, *callback_args, **callback_kwargs)
  File "/Users/fengdong/PycharmProjects/flowpredict000/flowpredict/warn_relaction_interface/view.py", line 102, in get_resu_process
    req_para = json.loads(req.body)
  File "/Applications/anaconda3/lib/python3.6/json/__init__.py", line 354, in loads
    return _default_decoder.decode(s)
  File "/Applications/anaconda3/lib/python3.6/json/decoder.py", line 339, in decode
    obj, end = self.raw_decode(s, idx=_w(s, 0).end())
  File "/Applications/anaconda3/lib/python3.6/json/decoder.py", line 357, in raw_decode
    raise JSONDecodeError("Expecting value", s, err.value) from None
json.decoder.JSONDecodeError: Expecting value: line 1 column 1 (char 0)
[2020-09-16 15:59:39,537] [basehttp.py:157] [basehttp:log_message] [ERROR]- "POST /get_resu_process HTTP/1.1" 500 145
[2020-09-16 16:03:23,213] [log.py:230] [log:log_response] [ERROR]- Internal Server Error: /get_resu_process
Traceback (most recent call last):
  File "/Applications/anaconda3/lib/python3.6/site-packages/django/core/handlers/exception.py", line 47, in inner
    response = get_response(request)
  File "/Applications/anaconda3/lib/python3.6/site-packages/django/core/handlers/base.py", line 179, in _get_response
    response = wrapped_callback(request, *callback_args, **callback_kwargs)
  File "/Users/fengdong/PycharmProjects/flowpredict000/flowpredict/warn_relaction_interface/view.py", line 102, in get_resu_process
    req_para = json.loads(req.body)
  File "/Applications/anaconda3/lib/python3.6/json/__init__.py", line 354, in loads
    return _default_decoder.decode(s)
  File "/Applications/anaconda3/lib/python3.6/json/decoder.py", line 339, in decode
    obj, end = self.raw_decode(s, idx=_w(s, 0).end())
  File "/Applications/anaconda3/lib/python3.6/json/decoder.py", line 357, in raw_decode
    raise JSONDecodeError("Expecting value", s, err.value) from None
json.decoder.JSONDecodeError: Expecting value: line 1 column 1 (char 0)
[2020-09-16 16:03:23,214] [basehttp.py:157] [basehttp:log_message] [ERROR]- "POST /get_resu_process HTTP/1.1" 500 145
[2020-09-16 16:03:44,371] [log.py:230] [log:log_response] [ERROR]- Internal Server Error: /get_resu_process
Traceback (most recent call last):
  File "/Applications/anaconda3/lib/python3.6/site-packages/django/core/handlers/exception.py", line 47, in inner
    response = get_response(request)
  File "/Applications/anaconda3/lib/python3.6/site-packages/django/core/handlers/base.py", line 179, in _get_response
    response = wrapped_callback(request, *callback_args, **callback_kwargs)
  File "/Users/fengdong/PycharmProjects/flowpredict000/flowpredict/warn_relaction_interface/view.py", line 102, in get_resu_process
    req_para = json.loads(req.body)
  File "/Applications/anaconda3/lib/python3.6/json/__init__.py", line 354, in loads
    return _default_decoder.decode(s)
  File "/Applications/anaconda3/lib/python3.6/json/decoder.py", line 339, in decode
    obj, end = self.raw_decode(s, idx=_w(s, 0).end())
  File "/Applications/anaconda3/lib/python3.6/json/decoder.py", line 357, in raw_decode
    raise JSONDecodeError("Expecting value", s, err.value) from None
json.decoder.JSONDecodeError: Expecting value: line 1 column 1 (char 0)
[2020-09-16 16:03:44,372] [basehttp.py:157] [basehttp:log_message] [ERROR]- "POST /get_resu_process HTTP/1.1" 500 145
[2020-09-16 16:04:26,853] [log.py:230] [log:log_response] [ERROR]- Internal Server Error: /get_resu_process
Traceback (most recent call last):
  File "/Applications/anaconda3/lib/python3.6/site-packages/django/core/handlers/exception.py", line 47, in inner
    response = get_response(request)
  File "/Applications/anaconda3/lib/python3.6/site-packages/django/core/handlers/base.py", line 179, in _get_response
    response = wrapped_callback(request, *callback_args, **callback_kwargs)
  File "/Users/fengdong/PycharmProjects/flowpredict000/flowpredict/warn_relaction_interface/view.py", line 102, in get_resu_process
    req_para = json.loads(req.body)
  File "/Applications/anaconda3/lib/python3.6/json/__init__.py", line 354, in loads
    return _default_decoder.decode(s)
  File "/Applications/anaconda3/lib/python3.6/json/decoder.py", line 339, in decode
    obj, end = self.raw_decode(s, idx=_w(s, 0).end())
  File "/Applications/anaconda3/lib/python3.6/json/decoder.py", line 357, in raw_decode
    raise JSONDecodeError("Expecting value", s, err.value) from None
json.decoder.JSONDecodeError: Expecting value: line 1 column 1 (char 0)
[2020-09-16 16:04:26,856] [basehttp.py:157] [basehttp:log_message] [ERROR]- "POST /get_resu_process HTTP/1.1" 500 145
[2020-09-16 16:04:41,328] [log.py:230] [log:log_response] [ERROR]- Internal Server Error: /get_resu_process
Traceback (most recent call last):
  File "/Applications/anaconda3/lib/python3.6/site-packages/django/core/handlers/exception.py", line 47, in inner
    response = get_response(request)
  File "/Applications/anaconda3/lib/python3.6/site-packages/django/core/handlers/base.py", line 179, in _get_response
    response = wrapped_callback(request, *callback_args, **callback_kwargs)
  File "/Users/fengdong/PycharmProjects/flowpredict000/flowpredict/warn_relaction_interface/view.py", line 102, in get_resu_process
    req_para = json.loads(req.body)
  File "/Applications/anaconda3/lib/python3.6/json/__init__.py", line 354, in loads
    return _default_decoder.decode(s)
  File "/Applications/anaconda3/lib/python3.6/json/decoder.py", line 339, in decode
    obj, end = self.raw_decode(s, idx=_w(s, 0).end())
  File "/Applications/anaconda3/lib/python3.6/json/decoder.py", line 357, in raw_decode
    raise JSONDecodeError("Expecting value", s, err.value) from None
json.decoder.JSONDecodeError: Expecting value: line 1 column 1 (char 0)
[2020-09-16 16:04:41,329] [basehttp.py:157] [basehttp:log_message] [ERROR]- "POST /get_resu_process HTTP/1.1" 500 145
[2020-09-16 16:04:58,835] [log.py:230] [log:log_response] [ERROR]- Internal Server Error: /get_resu_process
Traceback (most recent call last):
  File "/Applications/anaconda3/lib/python3.6/site-packages/django/core/handlers/exception.py", line 47, in inner
    response = get_response(request)
  File "/Applications/anaconda3/lib/python3.6/site-packages/django/core/handlers/base.py", line 179, in _get_response
    response = wrapped_callback(request, *callback_args, **callback_kwargs)
  File "/Users/fengdong/PycharmProjects/flowpredict000/flowpredict/warn_relaction_interface/view.py", line 102, in get_resu_process
    req_para = json.loads(req.body)
  File "/Applications/anaconda3/lib/python3.6/json/__init__.py", line 354, in loads
    return _default_decoder.decode(s)
  File "/Applications/anaconda3/lib/python3.6/json/decoder.py", line 339, in decode
    obj, end = self.raw_decode(s, idx=_w(s, 0).end())
  File "/Applications/anaconda3/lib/python3.6/json/decoder.py", line 357, in raw_decode
    raise JSONDecodeError("Expecting value", s, err.value) from None
json.decoder.JSONDecodeError: Expecting value: line 1 column 1 (char 0)
[2020-09-16 16:04:58,836] [basehttp.py:157] [basehttp:log_message] [ERROR]- "POST /get_resu_process HTTP/1.1" 500 145
[2020-09-16 16:06:11,206] [log.py:230] [log:log_response] [ERROR]- Internal Server Error: /get_resu_process
Traceback (most recent call last):
  File "/Applications/anaconda3/lib/python3.6/site-packages/django/core/handlers/exception.py", line 47, in inner
    response = get_response(request)
  File "/Applications/anaconda3/lib/python3.6/site-packages/django/core/handlers/base.py", line 179, in _get_response
    response = wrapped_callback(request, *callback_args, **callback_kwargs)
  File "/Users/fengdong/PycharmProjects/flowpredict000/flowpredict/warn_relaction_interface/view.py", line 102, in get_resu_process
    req_para = json.loads(req.body)
  File "/Applications/anaconda3/lib/python3.6/json/__init__.py", line 354, in loads
    return _default_decoder.decode(s)
  File "/Applications/anaconda3/lib/python3.6/json/decoder.py", line 339, in decode
    obj, end = self.raw_decode(s, idx=_w(s, 0).end())
  File "/Applications/anaconda3/lib/python3.6/json/decoder.py", line 357, in raw_decode
    raise JSONDecodeError("Expecting value", s, err.value) from None
json.decoder.JSONDecodeError: Expecting value: line 1 column 1 (char 0)
[2020-09-16 16:06:11,208] [basehttp.py:157] [basehttp:log_message] [ERROR]- "POST /get_resu_process HTTP/1.1" 500 145
[2020-09-16 16:07:03,859] [log.py:230] [log:log_response] [ERROR]- Internal Server Error: /get_resu_process
Traceback (most recent call last):
  File "/Applications/anaconda3/lib/python3.6/site-packages/django/core/handlers/exception.py", line 47, in inner
    response = get_response(request)
  File "/Applications/anaconda3/lib/python3.6/site-packages/django/core/handlers/base.py", line 179, in _get_response
    response = wrapped_callback(request, *callback_args, **callback_kwargs)
  File "/Users/fengdong/PycharmProjects/flowpredict000/flowpredict/warn_relaction_interface/view.py", line 102, in get_resu_process
    req_para = json.loads(req.body)
  File "/Applications/anaconda3/lib/python3.6/json/__init__.py", line 354, in loads
    return _default_decoder.decode(s)
  File "/Applications/anaconda3/lib/python3.6/json/decoder.py", line 339, in decode
    obj, end = self.raw_decode(s, idx=_w(s, 0).end())
  File "/Applications/anaconda3/lib/python3.6/json/decoder.py", line 357, in raw_decode
    raise JSONDecodeError("Expecting value", s, err.value) from None
json.decoder.JSONDecodeError: Expecting value: line 1 column 1 (char 0)
[2020-09-16 16:07:03,860] [basehttp.py:157] [basehttp:log_message] [ERROR]- "POST /get_resu_process HTTP/1.1" 500 145
[2020-09-16 16:07:09,356] [log.py:230] [log:log_response] [ERROR]- Internal Server Error: /get_resu_process
Traceback (most recent call last):
  File "/Applications/anaconda3/lib/python3.6/site-packages/django/core/handlers/exception.py", line 47, in inner
    response = get_response(request)
  File "/Applications/anaconda3/lib/python3.6/site-packages/django/core/handlers/base.py", line 179, in _get_response
    response = wrapped_callback(request, *callback_args, **callback_kwargs)
  File "/Users/fengdong/PycharmProjects/flowpredict000/flowpredict/warn_relaction_interface/view.py", line 102, in get_resu_process
    req_para = json.loads(req.body)
  File "/Applications/anaconda3/lib/python3.6/json/__init__.py", line 354, in loads
    return _default_decoder.decode(s)
  File "/Applications/anaconda3/lib/python3.6/json/decoder.py", line 339, in decode
    obj, end = self.raw_decode(s, idx=_w(s, 0).end())
  File "/Applications/anaconda3/lib/python3.6/json/decoder.py", line 357, in raw_decode
    raise JSONDecodeError("Expecting value", s, err.value) from None
json.decoder.JSONDecodeError: Expecting value: line 1 column 1 (char 0)
[2020-09-16 16:07:09,357] [basehttp.py:157] [basehttp:log_message] [ERROR]- "POST /get_resu_process HTTP/1.1" 500 145
[2020-09-16 16:07:10,165] [log.py:230] [log:log_response] [ERROR]- Internal Server Error: /get_resu_process
Traceback (most recent call last):
  File "/Applications/anaconda3/lib/python3.6/site-packages/django/core/handlers/exception.py", line 47, in inner
    response = get_response(request)
  File "/Applications/anaconda3/lib/python3.6/site-packages/django/core/handlers/base.py", line 179, in _get_response
    response = wrapped_callback(request, *callback_args, **callback_kwargs)
  File "/Users/fengdong/PycharmProjects/flowpredict000/flowpredict/warn_relaction_interface/view.py", line 102, in get_resu_process
    req_para = json.loads(req.body)
  File "/Applications/anaconda3/lib/python3.6/json/__init__.py", line 354, in loads
    return _default_decoder.decode(s)
  File "/Applications/anaconda3/lib/python3.6/json/decoder.py", line 339, in decode
    obj, end = self.raw_decode(s, idx=_w(s, 0).end())
  File "/Applications/anaconda3/lib/python3.6/json/decoder.py", line 357, in raw_decode
    raise JSONDecodeError("Expecting value", s, err.value) from None
json.decoder.JSONDecodeError: Expecting value: line 1 column 1 (char 0)
[2020-09-16 16:07:10,167] [basehttp.py:157] [basehttp:log_message] [ERROR]- "POST /get_resu_process HTTP/1.1" 500 145
[2020-09-16 16:07:22,205] [log.py:230] [log:log_response] [ERROR]- Internal Server Error: /get_resu_process
Traceback (most recent call last):
  File "/Applications/anaconda3/lib/python3.6/site-packages/django/core/handlers/exception.py", line 47, in inner
    response = get_response(request)
  File "/Applications/anaconda3/lib/python3.6/site-packages/django/core/handlers/base.py", line 179, in _get_response
    response = wrapped_callback(request, *callback_args, **callback_kwargs)
  File "/Users/fengdong/PycharmProjects/flowpredict000/flowpredict/warn_relaction_interface/view.py", line 102, in get_resu_process
    req_para = json.loads(req.body)
  File "/Applications/anaconda3/lib/python3.6/json/__init__.py", line 354, in loads
    return _default_decoder.decode(s)
  File "/Applications/anaconda3/lib/python3.6/json/decoder.py", line 339, in decode
    obj, end = self.raw_decode(s, idx=_w(s, 0).end())
  File "/Applications/anaconda3/lib/python3.6/json/decoder.py", line 357, in raw_decode
    raise JSONDecodeError("Expecting value", s, err.value) from None
json.decoder.JSONDecodeError: Expecting value: line 1 column 1 (char 0)
[2020-09-16 16:07:22,206] [basehttp.py:157] [basehttp:log_message] [ERROR]- "POST /get_resu_process HTTP/1.1" 500 145
[2020-09-16 16:07:58,186] [log.py:230] [log:log_response] [ERROR]- Internal Server Error: /get_resu_process
Traceback (most recent call last):
  File "/Applications/anaconda3/lib/python3.6/site-packages/django/core/handlers/exception.py", line 47, in inner
    response = get_response(request)
  File "/Applications/anaconda3/lib/python3.6/site-packages/django/core/handlers/base.py", line 179, in _get_response
    response = wrapped_callback(request, *callback_args, **callback_kwargs)
  File "/Users/fengdong/PycharmProjects/flowpredict000/flowpredict/warn_relaction_interface/view.py", line 102, in get_resu_process
    req_para = json.loads(req.body)
  File "/Applications/anaconda3/lib/python3.6/json/__init__.py", line 354, in loads
    return _default_decoder.decode(s)
  File "/Applications/anaconda3/lib/python3.6/json/decoder.py", line 339, in decode
    obj, end = self.raw_decode(s, idx=_w(s, 0).end())
  File "/Applications/anaconda3/lib/python3.6/json/decoder.py", line 357, in raw_decode
    raise JSONDecodeError("Expecting value", s, err.value) from None
json.decoder.JSONDecodeError: Expecting value: line 1 column 1 (char 0)
[2020-09-16 16:07:58,187] [basehttp.py:157] [basehttp:log_message] [ERROR]- "POST /get_resu_process HTTP/1.1" 500 145
[2020-09-16 16:08:06,138] [log.py:230] [log:log_response] [ERROR]- Internal Server Error: /get_resu_process
Traceback (most recent call last):
  File "/Applications/anaconda3/lib/python3.6/site-packages/django/core/handlers/exception.py", line 47, in inner
    response = get_response(request)
  File "/Applications/anaconda3/lib/python3.6/site-packages/django/core/handlers/base.py", line 179, in _get_response
    response = wrapped_callback(request, *callback_args, **callback_kwargs)
  File "/Users/fengdong/PycharmProjects/flowpredict000/flowpredict/warn_relaction_interface/view.py", line 102, in get_resu_process
    req_para = json.loads(req.body)
  File "/Applications/anaconda3/lib/python3.6/json/__init__.py", line 354, in loads
    return _default_decoder.decode(s)
  File "/Applications/anaconda3/lib/python3.6/json/decoder.py", line 339, in decode
    obj, end = self.raw_decode(s, idx=_w(s, 0).end())
  File "/Applications/anaconda3/lib/python3.6/json/decoder.py", line 357, in raw_decode
    raise JSONDecodeError("Expecting value", s, err.value) from None
json.decoder.JSONDecodeError: Expecting value: line 1 column 1 (char 0)
[2020-09-16 16:08:06,141] [basehttp.py:157] [basehttp:log_message] [ERROR]- "POST /get_resu_process HTTP/1.1" 500 145
[2020-09-16 16:08:31,388] [log.py:230] [log:log_response] [ERROR]- Internal Server Error: /get_resu_process
Traceback (most recent call last):
  File "/Applications/anaconda3/lib/python3.6/site-packages/django/core/handlers/exception.py", line 47, in inner
    response = get_response(request)
  File "/Applications/anaconda3/lib/python3.6/site-packages/django/core/handlers/base.py", line 179, in _get_response
    response = wrapped_callback(request, *callback_args, **callback_kwargs)
  File "/Users/fengdong/PycharmProjects/flowpredict000/flowpredict/warn_relaction_interface/view.py", line 102, in get_resu_process
    req_para = json.loads(req.body)
  File "/Applications/anaconda3/lib/python3.6/json/__init__.py", line 354, in loads
    return _default_decoder.decode(s)
  File "/Applications/anaconda3/lib/python3.6/json/decoder.py", line 339, in decode
    obj, end = self.raw_decode(s, idx=_w(s, 0).end())
  File "/Applications/anaconda3/lib/python3.6/json/decoder.py", line 357, in raw_decode
    raise JSONDecodeError("Expecting value", s, err.value) from None
json.decoder.JSONDecodeError: Expecting value: line 1 column 1 (char 0)
[2020-09-16 16:08:31,389] [basehttp.py:157] [basehttp:log_message] [ERROR]- "POST /get_resu_process?work_id=48aaa2e8deaa3d4f27142445bfc36cd1 HTTP/1.1" 500 145
[2020-09-16 16:08:42,014] [log.py:230] [log:log_response] [ERROR]- Internal Server Error: /get_resu_process
Traceback (most recent call last):
  File "/Applications/anaconda3/lib/python3.6/site-packages/django/core/handlers/exception.py", line 47, in inner
    response = get_response(request)
  File "/Applications/anaconda3/lib/python3.6/site-packages/django/core/handlers/base.py", line 179, in _get_response
    response = wrapped_callback(request, *callback_args, **callback_kwargs)
  File "/Users/fengdong/PycharmProjects/flowpredict000/flowpredict/warn_relaction_interface/view.py", line 102, in get_resu_process
    req_para = json.loads(req.body)
  File "/Applications/anaconda3/lib/python3.6/json/__init__.py", line 354, in loads
    return _default_decoder.decode(s)
  File "/Applications/anaconda3/lib/python3.6/json/decoder.py", line 339, in decode
    obj, end = self.raw_decode(s, idx=_w(s, 0).end())
  File "/Applications/anaconda3/lib/python3.6/json/decoder.py", line 357, in raw_decode
    raise JSONDecodeError("Expecting value", s, err.value) from None
json.decoder.JSONDecodeError: Expecting value: line 1 column 1 (char 0)
[2020-09-16 16:08:42,016] [basehttp.py:157] [basehttp:log_message] [ERROR]- "POST /get_resu_process?work_id=48aaa2e8deaa3d4f27142445bfc36cd1 HTTP/1.1" 500 145
[2020-09-16 16:09:01,954] [log.py:230] [log:log_response] [ERROR]- Internal Server Error: /get_resu_process
Traceback (most recent call last):
  File "/Applications/anaconda3/lib/python3.6/site-packages/django/core/handlers/exception.py", line 47, in inner
    response = get_response(request)
  File "/Applications/anaconda3/lib/python3.6/site-packages/django/core/handlers/base.py", line 179, in _get_response
    response = wrapped_callback(request, *callback_args, **callback_kwargs)
  File "/Users/fengdong/PycharmProjects/flowpredict000/flowpredict/warn_relaction_interface/view.py", line 102, in get_resu_process
    req_para = json.loads(req.body)
  File "/Applications/anaconda3/lib/python3.6/json/__init__.py", line 354, in loads
    return _default_decoder.decode(s)
  File "/Applications/anaconda3/lib/python3.6/json/decoder.py", line 339, in decode
    obj, end = self.raw_decode(s, idx=_w(s, 0).end())
  File "/Applications/anaconda3/lib/python3.6/json/decoder.py", line 357, in raw_decode
    raise JSONDecodeError("Expecting value", s, err.value) from None
json.decoder.JSONDecodeError: Expecting value: line 1 column 1 (char 0)
[2020-09-16 16:09:01,955] [basehttp.py:157] [basehttp:log_message] [ERROR]- "POST /get_resu_process?work_id=67c35597-7cc2-45ab-8fe5-64ba13f09fe0 HTTP/1.1" 500 145
[2020-09-16 16:09:13,656] [autoreload.py:612] [autoreload:run_with_reloader] [INFO]- Watching for file changes with StatReloader
[2020-09-16 16:09:22,915] [log.py:230] [log:log_response] [ERROR]- Internal Server Error: /get_resu_process
Traceback (most recent call last):
  File "/Applications/anaconda3/lib/python3.6/site-packages/django/core/handlers/exception.py", line 47, in inner
    response = get_response(request)
  File "/Applications/anaconda3/lib/python3.6/site-packages/django/core/handlers/base.py", line 179, in _get_response
    response = wrapped_callback(request, *callback_args, **callback_kwargs)
  File "/Users/fengdong/PycharmProjects/flowpredict000/flowpredict/warn_relaction_interface/view.py", line 102, in get_resu_process
    req_para = json.loads(req.body)
  File "/Applications/anaconda3/lib/python3.6/json/__init__.py", line 354, in loads
    return _default_decoder.decode(s)
  File "/Applications/anaconda3/lib/python3.6/json/decoder.py", line 339, in decode
    obj, end = self.raw_decode(s, idx=_w(s, 0).end())
  File "/Applications/anaconda3/lib/python3.6/json/decoder.py", line 357, in raw_decode
    raise JSONDecodeError("Expecting value", s, err.value) from None
json.decoder.JSONDecodeError: Expecting value: line 1 column 1 (char 0)
[2020-09-16 16:09:22,921] [basehttp.py:157] [basehttp:log_message] [ERROR]- "POST /get_resu_process?work_id=67c35597-7cc2-45ab-8fe5-64ba13f09fe0 HTTP/1.1" 500 145
[2020-09-16 16:10:04,577] [log.py:230] [log:log_response] [ERROR]- Internal Server Error: /get_resu_process
Traceback (most recent call last):
  File "/Applications/anaconda3/lib/python3.6/site-packages/django/core/handlers/exception.py", line 47, in inner
    response = get_response(request)
  File "/Applications/anaconda3/lib/python3.6/site-packages/django/core/handlers/base.py", line 179, in _get_response
    response = wrapped_callback(request, *callback_args, **callback_kwargs)
  File "/Users/fengdong/PycharmProjects/flowpredict000/flowpredict/warn_relaction_interface/view.py", line 102, in get_resu_process
    req_para = json.loads(req.body)
  File "/Applications/anaconda3/lib/python3.6/json/__init__.py", line 354, in loads
    return _default_decoder.decode(s)
  File "/Applications/anaconda3/lib/python3.6/json/decoder.py", line 339, in decode
    obj, end = self.raw_decode(s, idx=_w(s, 0).end())
  File "/Applications/anaconda3/lib/python3.6/json/decoder.py", line 357, in raw_decode
    raise JSONDecodeError("Expecting value", s, err.value) from None
json.decoder.JSONDecodeError: Expecting value: line 1 column 1 (char 0)
[2020-09-16 16:10:04,578] [basehttp.py:157] [basehttp:log_message] [ERROR]- "POST /get_resu_process?%22work_id%22=%2248aaa2e8deaa3d4f27142445bfc36cd1%22 HTTP/1.1" 500 145
[2020-09-16 16:10:19,268] [log.py:230] [log:log_response] [ERROR]- Internal Server Error: /get_resu_process
Traceback (most recent call last):
  File "/Applications/anaconda3/lib/python3.6/site-packages/django/core/handlers/exception.py", line 47, in inner
    response = get_response(request)
  File "/Applications/anaconda3/lib/python3.6/site-packages/django/core/handlers/base.py", line 179, in _get_response
    response = wrapped_callback(request, *callback_args, **callback_kwargs)
  File "/Users/fengdong/PycharmProjects/flowpredict000/flowpredict/warn_relaction_interface/view.py", line 102, in get_resu_process
    req_para = json.loads(req.body)
  File "/Applications/anaconda3/lib/python3.6/json/__init__.py", line 354, in loads
    return _default_decoder.decode(s)
  File "/Applications/anaconda3/lib/python3.6/json/decoder.py", line 339, in decode
    obj, end = self.raw_decode(s, idx=_w(s, 0).end())
  File "/Applications/anaconda3/lib/python3.6/json/decoder.py", line 357, in raw_decode
    raise JSONDecodeError("Expecting value", s, err.value) from None
json.decoder.JSONDecodeError: Expecting value: line 1 column 1 (char 0)
[2020-09-16 16:10:19,269] [basehttp.py:157] [basehttp:log_message] [ERROR]- "POST /get_resu_process?%22work_id%22=%2248aaa2e8deaa3d4f27142445bfc36cd1%22 HTTP/1.1" 500 145
[2020-09-16 16:10:24,554] [log.py:230] [log:log_response] [ERROR]- Internal Server Error: /get_resu_process
Traceback (most recent call last):
  File "/Applications/anaconda3/lib/python3.6/site-packages/django/core/handlers/exception.py", line 47, in inner
    response = get_response(request)
  File "/Applications/anaconda3/lib/python3.6/site-packages/django/core/handlers/base.py", line 179, in _get_response
    response = wrapped_callback(request, *callback_args, **callback_kwargs)
  File "/Users/fengdong/PycharmProjects/flowpredict000/flowpredict/warn_relaction_interface/view.py", line 102, in get_resu_process
    req_para = json.loads(req.body)
  File "/Applications/anaconda3/lib/python3.6/json/__init__.py", line 354, in loads
    return _default_decoder.decode(s)
  File "/Applications/anaconda3/lib/python3.6/json/decoder.py", line 339, in decode
    obj, end = self.raw_decode(s, idx=_w(s, 0).end())
  File "/Applications/anaconda3/lib/python3.6/json/decoder.py", line 357, in raw_decode
    raise JSONDecodeError("Expecting value", s, err.value) from None
json.decoder.JSONDecodeError: Expecting value: line 1 column 1 (char 0)
[2020-09-16 16:10:24,555] [basehttp.py:157] [basehttp:log_message] [ERROR]- "POST /get_resu_process?work_id=%2248aaa2e8deaa3d4f27142445bfc36cd1%22 HTTP/1.1" 500 145
[2020-09-16 16:10:25,334] [log.py:230] [log:log_response] [ERROR]- Internal Server Error: /get_resu_process
Traceback (most recent call last):
  File "/Applications/anaconda3/lib/python3.6/site-packages/django/core/handlers/exception.py", line 47, in inner
    response = get_response(request)
  File "/Applications/anaconda3/lib/python3.6/site-packages/django/core/handlers/base.py", line 179, in _get_response
    response = wrapped_callback(request, *callback_args, **callback_kwargs)
  File "/Users/fengdong/PycharmProjects/flowpredict000/flowpredict/warn_relaction_interface/view.py", line 102, in get_resu_process
    req_para = json.loads(req.body)
  File "/Applications/anaconda3/lib/python3.6/json/__init__.py", line 354, in loads
    return _default_decoder.decode(s)
  File "/Applications/anaconda3/lib/python3.6/json/decoder.py", line 339, in decode
    obj, end = self.raw_decode(s, idx=_w(s, 0).end())
  File "/Applications/anaconda3/lib/python3.6/json/decoder.py", line 357, in raw_decode
    raise JSONDecodeError("Expecting value", s, err.value) from None
json.decoder.JSONDecodeError: Expecting value: line 1 column 1 (char 0)
[2020-09-16 16:10:25,335] [basehttp.py:157] [basehttp:log_message] [ERROR]- "POST /get_resu_process?work_id=%2248aaa2e8deaa3d4f27142445bfc36cd1%22 HTTP/1.1" 500 145
[2020-09-16 16:10:26,188] [log.py:230] [log:log_response] [ERROR]- Internal Server Error: /get_resu_process
Traceback (most recent call last):
  File "/Applications/anaconda3/lib/python3.6/site-packages/django/core/handlers/exception.py", line 47, in inner
    response = get_response(request)
  File "/Applications/anaconda3/lib/python3.6/site-packages/django/core/handlers/base.py", line 179, in _get_response
    response = wrapped_callback(request, *callback_args, **callback_kwargs)
  File "/Users/fengdong/PycharmProjects/flowpredict000/flowpredict/warn_relaction_interface/view.py", line 102, in get_resu_process
    req_para = json.loads(req.body)
  File "/Applications/anaconda3/lib/python3.6/json/__init__.py", line 354, in loads
    return _default_decoder.decode(s)
  File "/Applications/anaconda3/lib/python3.6/json/decoder.py", line 339, in decode
    obj, end = self.raw_decode(s, idx=_w(s, 0).end())
  File "/Applications/anaconda3/lib/python3.6/json/decoder.py", line 357, in raw_decode
    raise JSONDecodeError("Expecting value", s, err.value) from None
json.decoder.JSONDecodeError: Expecting value: line 1 column 1 (char 0)
[2020-09-16 16:10:26,189] [basehttp.py:157] [basehttp:log_message] [ERROR]- "POST /get_resu_process?work_id=%2248aaa2e8deaa3d4f27142445bfc36cd1%22 HTTP/1.1" 500 145
[2020-09-16 16:10:31,362] [log.py:230] [log:log_response] [ERROR]- Internal Server Error: /get_resu_process
Traceback (most recent call last):
  File "/Applications/anaconda3/lib/python3.6/site-packages/django/core/handlers/exception.py", line 47, in inner
    response = get_response(request)
  File "/Applications/anaconda3/lib/python3.6/site-packages/django/core/handlers/base.py", line 179, in _get_response
    response = wrapped_callback(request, *callback_args, **callback_kwargs)
  File "/Users/fengdong/PycharmProjects/flowpredict000/flowpredict/warn_relaction_interface/view.py", line 102, in get_resu_process
    req_para = json.loads(req.body)
  File "/Applications/anaconda3/lib/python3.6/json/__init__.py", line 354, in loads
    return _default_decoder.decode(s)
  File "/Applications/anaconda3/lib/python3.6/json/decoder.py", line 339, in decode
    obj, end = self.raw_decode(s, idx=_w(s, 0).end())
  File "/Applications/anaconda3/lib/python3.6/json/decoder.py", line 357, in raw_decode
    raise JSONDecodeError("Expecting value", s, err.value) from None
json.decoder.JSONDecodeError: Expecting value: line 1 column 1 (char 0)
[2020-09-16 16:10:31,363] [basehttp.py:157] [basehttp:log_message] [ERROR]- "POST /get_resu_process?work_id=48aaa2e8deaa3d4f27142445bfc36cd1 HTTP/1.1" 500 145
[2020-09-16 16:15:35,242] [log.py:230] [log:log_response] [ERROR]- Internal Server Error: /get_resu_process
Traceback (most recent call last):
  File "/Applications/anaconda3/lib/python3.6/site-packages/django/core/handlers/exception.py", line 47, in inner
    response = get_response(request)
  File "/Applications/anaconda3/lib/python3.6/site-packages/django/core/handlers/base.py", line 179, in _get_response
    response = wrapped_callback(request, *callback_args, **callback_kwargs)
  File "/Users/fengdong/PycharmProjects/flowpredict000/flowpredict/warn_relaction_interface/view.py", line 102, in get_resu_process
    req_para = json.loads(req.body)
  File "/Applications/anaconda3/lib/python3.6/json/__init__.py", line 354, in loads
    return _default_decoder.decode(s)
  File "/Applications/anaconda3/lib/python3.6/json/decoder.py", line 339, in decode
    obj, end = self.raw_decode(s, idx=_w(s, 0).end())
  File "/Applications/anaconda3/lib/python3.6/json/decoder.py", line 357, in raw_decode
    raise JSONDecodeError("Expecting value", s, err.value) from None
json.decoder.JSONDecodeError: Expecting value: line 1 column 1 (char 0)
[2020-09-16 16:15:35,243] [basehttp.py:157] [basehttp:log_message] [ERROR]- "POST /get_resu_process?work_id=48aaa2e8deaa3d4f27142445bfc36cd1?work_id=48aaa2e8deaa3d4f27142445bfc36cd1 HTTP/1.1" 500 145
[2020-09-16 16:15:37,055] [log.py:230] [log:log_response] [ERROR]- Internal Server Error: /get_resu_process
Traceback (most recent call last):
  File "/Applications/anaconda3/lib/python3.6/site-packages/django/core/handlers/exception.py", line 47, in inner
    response = get_response(request)
  File "/Applications/anaconda3/lib/python3.6/site-packages/django/core/handlers/base.py", line 179, in _get_response
    response = wrapped_callback(request, *callback_args, **callback_kwargs)
  File "/Users/fengdong/PycharmProjects/flowpredict000/flowpredict/warn_relaction_interface/view.py", line 102, in get_resu_process
    req_para = json.loads(req.body)
  File "/Applications/anaconda3/lib/python3.6/json/__init__.py", line 354, in loads
    return _default_decoder.decode(s)
  File "/Applications/anaconda3/lib/python3.6/json/decoder.py", line 339, in decode
    obj, end = self.raw_decode(s, idx=_w(s, 0).end())
  File "/Applications/anaconda3/lib/python3.6/json/decoder.py", line 357, in raw_decode
    raise JSONDecodeError("Expecting value", s, err.value) from None
json.decoder.JSONDecodeError: Expecting value: line 1 column 1 (char 0)
[2020-09-16 16:15:37,056] [basehttp.py:157] [basehttp:log_message] [ERROR]- "POST /get_resu_process?work_id=48aaa2e8deaa3d4f27142445bfc36cd1?work_id=48aaa2e8deaa3d4f27142445bfc36cd1 HTTP/1.1" 500 145
[2020-09-16 16:20:47,748] [autoreload.py:612] [autoreload:run_with_reloader] [INFO]- Watching for file changes with StatReloader
[2020-09-16 16:20:57,977] [basehttp.py:157] [basehttp:log_message] [INFO]- "POST / HTTP/1.1" 200 67
[2020-09-16 16:22:21,545] [log.py:230] [log:log_response] [ERROR]- Internal Server Error: /get_resu_process
Traceback (most recent call last):
  File "/Applications/anaconda3/lib/python3.6/site-packages/django/core/handlers/exception.py", line 47, in inner
    response = get_response(request)
  File "/Applications/anaconda3/lib/python3.6/site-packages/django/core/handlers/base.py", line 179, in _get_response
    response = wrapped_callback(request, *callback_args, **callback_kwargs)
  File "/Users/fengdong/PycharmProjects/flowpredict000/flowpredict/warn_relaction_interface/view.py", line 102, in get_resu_process
    req_para = json.loads(req.body)
  File "/Applications/anaconda3/lib/python3.6/json/__init__.py", line 354, in loads
    return _default_decoder.decode(s)
  File "/Applications/anaconda3/lib/python3.6/json/decoder.py", line 339, in decode
    obj, end = self.raw_decode(s, idx=_w(s, 0).end())
  File "/Applications/anaconda3/lib/python3.6/json/decoder.py", line 357, in raw_decode
    raise JSONDecodeError("Expecting value", s, err.value) from None
json.decoder.JSONDecodeError: Expecting value: line 1 column 1 (char 0)
[2020-09-16 16:22:21,550] [basehttp.py:157] [basehttp:log_message] [ERROR]- "POST /get_resu_process HTTP/1.1" 500 145
[2020-09-16 16:22:47,254] [log.py:230] [log:log_response] [ERROR]- Internal Server Error: /get_resu_process
Traceback (most recent call last):
  File "/Applications/anaconda3/lib/python3.6/site-packages/django/core/handlers/exception.py", line 47, in inner
    response = get_response(request)
  File "/Applications/anaconda3/lib/python3.6/site-packages/django/core/handlers/base.py", line 179, in _get_response
    response = wrapped_callback(request, *callback_args, **callback_kwargs)
  File "/Users/fengdong/PycharmProjects/flowpredict000/flowpredict/warn_relaction_interface/view.py", line 102, in get_resu_process
    req_para = json.loads(req.body)
  File "/Applications/anaconda3/lib/python3.6/json/__init__.py", line 354, in loads
    return _default_decoder.decode(s)
  File "/Applications/anaconda3/lib/python3.6/json/decoder.py", line 339, in decode
    obj, end = self.raw_decode(s, idx=_w(s, 0).end())
  File "/Applications/anaconda3/lib/python3.6/json/decoder.py", line 357, in raw_decode
    raise JSONDecodeError("Expecting value", s, err.value) from None
json.decoder.JSONDecodeError: Expecting value: line 1 column 1 (char 0)
[2020-09-16 16:22:47,255] [basehttp.py:157] [basehttp:log_message] [ERROR]- "POST /get_resu_process?work_id=48aaa2e8deaa3d4f27142445bfc36cd1 HTTP/1.1" 500 145
[2020-09-16 16:25:23,468] [log.py:230] [log:log_response] [ERROR]- Internal Server Error: /get_resu_process
Traceback (most recent call last):
  File "/Applications/anaconda3/lib/python3.6/site-packages/django/core/handlers/exception.py", line 47, in inner
    response = get_response(request)
  File "/Applications/anaconda3/lib/python3.6/site-packages/django/core/handlers/base.py", line 179, in _get_response
    response = wrapped_callback(request, *callback_args, **callback_kwargs)
  File "/Users/fengdong/PycharmProjects/flowpredict000/flowpredict/warn_relaction_interface/view.py", line 102, in get_resu_process
    req_para = json.loads(req.body)
  File "/Applications/anaconda3/lib/python3.6/json/__init__.py", line 354, in loads
    return _default_decoder.decode(s)
  File "/Applications/anaconda3/lib/python3.6/json/decoder.py", line 339, in decode
    obj, end = self.raw_decode(s, idx=_w(s, 0).end())
  File "/Applications/anaconda3/lib/python3.6/json/decoder.py", line 357, in raw_decode
    raise JSONDecodeError("Expecting value", s, err.value) from None
json.decoder.JSONDecodeError: Expecting value: line 1 column 1 (char 0)
[2020-09-16 16:25:23,469] [basehttp.py:157] [basehttp:log_message] [ERROR]- "POST /get_resu_process?work_id=48aaa2e8deaa3d4f27142445bfc36cd1 HTTP/1.1" 500 145
[2020-09-16 16:25:23,666] [autoreload.py:236] [autoreload:trigger_reload] [INFO]- /Users/fengdong/PycharmProjects/flowpredict000/flowpredict/warn_relaction_interface/view.py changed, reloading.
[2020-09-16 16:25:24,615] [autoreload.py:612] [autoreload:run_with_reloader] [INFO]- Watching for file changes with StatReloader
[2020-09-16 16:25:40,010] [log.py:230] [log:log_response] [ERROR]- Internal Server Error: /get_resu_process
Traceback (most recent call last):
  File "/Applications/anaconda3/lib/python3.6/site-packages/django/core/handlers/exception.py", line 47, in inner
    response = get_response(request)
  File "/Applications/anaconda3/lib/python3.6/site-packages/django/core/handlers/base.py", line 179, in _get_response
    response = wrapped_callback(request, *callback_args, **callback_kwargs)
  File "/Users/fengdong/PycharmProjects/flowpredict000/flowpredict/warn_relaction_interface/view.py", line 102, in get_resu_process
    req_para = json.loads(req.body)
  File "/Applications/anaconda3/lib/python3.6/json/__init__.py", line 354, in loads
    return _default_decoder.decode(s)
  File "/Applications/anaconda3/lib/python3.6/json/decoder.py", line 339, in decode
    obj, end = self.raw_decode(s, idx=_w(s, 0).end())
  File "/Applications/anaconda3/lib/python3.6/json/decoder.py", line 357, in raw_decode
    raise JSONDecodeError("Expecting value", s, err.value) from None
json.decoder.JSONDecodeError: Expecting value: line 1 column 1 (char 0)
[2020-09-16 16:25:40,015] [basehttp.py:157] [basehttp:log_message] [ERROR]- "POST /get_resu_process?work_id=48aaa2e8deaa3d4f27142445bfc36cd1 HTTP/1.1" 500 145
[2020-09-16 16:25:51,372] [log.py:230] [log:log_response] [ERROR]- Internal Server Error: /get_resu_process
Traceback (most recent call last):
  File "/Applications/anaconda3/lib/python3.6/site-packages/django/core/handlers/exception.py", line 47, in inner
    response = get_response(request)
  File "/Applications/anaconda3/lib/python3.6/site-packages/django/core/handlers/base.py", line 179, in _get_response
    response = wrapped_callback(request, *callback_args, **callback_kwargs)
  File "/Users/fengdong/PycharmProjects/flowpredict000/flowpredict/warn_relaction_interface/view.py", line 102, in get_resu_process
    req_para = json.loads(req.body)
  File "/Applications/anaconda3/lib/python3.6/json/__init__.py", line 354, in loads
    return _default_decoder.decode(s)
  File "/Applications/anaconda3/lib/python3.6/json/decoder.py", line 339, in decode
    obj, end = self.raw_decode(s, idx=_w(s, 0).end())
  File "/Applications/anaconda3/lib/python3.6/json/decoder.py", line 357, in raw_decode
    raise JSONDecodeError("Expecting value", s, err.value) from None
json.decoder.JSONDecodeError: Expecting value: line 1 column 1 (char 0)
[2020-09-16 16:25:51,372] [basehttp.py:157] [basehttp:log_message] [ERROR]- "POST /get_resu_process?work_id=48aaa2e8deaa3d4f27142445bfc36cd1 HTTP/1.1" 500 145
[2020-09-16 16:25:53,069] [log.py:230] [log:log_response] [ERROR]- Internal Server Error: /get_resu_process
Traceback (most recent call last):
  File "/Applications/anaconda3/lib/python3.6/site-packages/django/core/handlers/exception.py", line 47, in inner
    response = get_response(request)
  File "/Applications/anaconda3/lib/python3.6/site-packages/django/core/handlers/base.py", line 179, in _get_response
    response = wrapped_callback(request, *callback_args, **callback_kwargs)
  File "/Users/fengdong/PycharmProjects/flowpredict000/flowpredict/warn_relaction_interface/view.py", line 102, in get_resu_process
    req_para = json.loads(req.body)
  File "/Applications/anaconda3/lib/python3.6/json/__init__.py", line 354, in loads
    return _default_decoder.decode(s)
  File "/Applications/anaconda3/lib/python3.6/json/decoder.py", line 339, in decode
    obj, end = self.raw_decode(s, idx=_w(s, 0).end())
  File "/Applications/anaconda3/lib/python3.6/json/decoder.py", line 357, in raw_decode
    raise JSONDecodeError("Expecting value", s, err.value) from None
json.decoder.JSONDecodeError: Expecting value: line 1 column 1 (char 0)
[2020-09-16 16:25:53,070] [basehttp.py:157] [basehttp:log_message] [ERROR]- "POST /get_resu_process?work_id=48aaa2e8deaa3d4f27142445bfc36cd1 HTTP/1.1" 500 145
[2020-09-16 16:25:55,634] [log.py:230] [log:log_response] [ERROR]- Internal Server Error: /get_resu_process
Traceback (most recent call last):
  File "/Applications/anaconda3/lib/python3.6/site-packages/django/core/handlers/exception.py", line 47, in inner
    response = get_response(request)
  File "/Applications/anaconda3/lib/python3.6/site-packages/django/core/handlers/base.py", line 179, in _get_response
    response = wrapped_callback(request, *callback_args, **callback_kwargs)
  File "/Users/fengdong/PycharmProjects/flowpredict000/flowpredict/warn_relaction_interface/view.py", line 102, in get_resu_process
    req_para = json.loads(req.body)
  File "/Applications/anaconda3/lib/python3.6/json/__init__.py", line 354, in loads
    return _default_decoder.decode(s)
  File "/Applications/anaconda3/lib/python3.6/json/decoder.py", line 339, in decode
    obj, end = self.raw_decode(s, idx=_w(s, 0).end())
  File "/Applications/anaconda3/lib/python3.6/json/decoder.py", line 357, in raw_decode
    raise JSONDecodeError("Expecting value", s, err.value) from None
json.decoder.JSONDecodeError: Expecting value: line 1 column 1 (char 0)
[2020-09-16 16:25:55,635] [basehttp.py:157] [basehttp:log_message] [ERROR]- "POST /get_resu_process?work_id=48aaa2e8deaa3d4f27142445bfc36cd1 HTTP/1.1" 500 145
[2020-09-16 16:25:56,971] [log.py:230] [log:log_response] [ERROR]- Internal Server Error: /get_resu_process
Traceback (most recent call last):
  File "/Applications/anaconda3/lib/python3.6/site-packages/django/core/handlers/exception.py", line 47, in inner
    response = get_response(request)
  File "/Applications/anaconda3/lib/python3.6/site-packages/django/core/handlers/base.py", line 179, in _get_response
    response = wrapped_callback(request, *callback_args, **callback_kwargs)
  File "/Users/fengdong/PycharmProjects/flowpredict000/flowpredict/warn_relaction_interface/view.py", line 102, in get_resu_process
    req_para = json.loads(req.body)
  File "/Applications/anaconda3/lib/python3.6/json/__init__.py", line 354, in loads
    return _default_decoder.decode(s)
  File "/Applications/anaconda3/lib/python3.6/json/decoder.py", line 339, in decode
    obj, end = self.raw_decode(s, idx=_w(s, 0).end())
  File "/Applications/anaconda3/lib/python3.6/json/decoder.py", line 357, in raw_decode
    raise JSONDecodeError("Expecting value", s, err.value) from None
json.decoder.JSONDecodeError: Expecting value: line 1 column 1 (char 0)
[2020-09-16 16:25:56,973] [basehttp.py:157] [basehttp:log_message] [ERROR]- "POST /get_resu_process?work_id=48aaa2e8deaa3d4f27142445bfc36cd1 HTTP/1.1" 500 145
[2020-09-16 16:25:57,984] [log.py:230] [log:log_response] [ERROR]- Internal Server Error: /get_resu_process
Traceback (most recent call last):
  File "/Applications/anaconda3/lib/python3.6/site-packages/django/core/handlers/exception.py", line 47, in inner
    response = get_response(request)
  File "/Applications/anaconda3/lib/python3.6/site-packages/django/core/handlers/base.py", line 179, in _get_response
    response = wrapped_callback(request, *callback_args, **callback_kwargs)
  File "/Users/fengdong/PycharmProjects/flowpredict000/flowpredict/warn_relaction_interface/view.py", line 102, in get_resu_process
    req_para = json.loads(req.body)
  File "/Applications/anaconda3/lib/python3.6/json/__init__.py", line 354, in loads
    return _default_decoder.decode(s)
  File "/Applications/anaconda3/lib/python3.6/json/decoder.py", line 339, in decode
    obj, end = self.raw_decode(s, idx=_w(s, 0).end())
  File "/Applications/anaconda3/lib/python3.6/json/decoder.py", line 357, in raw_decode
    raise JSONDecodeError("Expecting value", s, err.value) from None
json.decoder.JSONDecodeError: Expecting value: line 1 column 1 (char 0)
[2020-09-16 16:25:57,985] [basehttp.py:157] [basehttp:log_message] [ERROR]- "POST /get_resu_process?work_id=48aaa2e8deaa3d4f27142445bfc36cd1 HTTP/1.1" 500 145
[2020-09-16 16:26:14,382] [autoreload.py:236] [autoreload:trigger_reload] [INFO]- /Users/fengdong/PycharmProjects/flowpredict000/flowpredict/warn_relaction_interface/view.py changed, reloading.
[2020-09-16 16:26:15,245] [autoreload.py:612] [autoreload:run_with_reloader] [INFO]- Watching for file changes with StatReloader
[2020-09-16 16:26:18,265] [log.py:230] [log:log_response] [ERROR]- Internal Server Error: /get_resu_process
Traceback (most recent call last):
  File "/Applications/anaconda3/lib/python3.6/site-packages/django/core/handlers/exception.py", line 47, in inner
    response = get_response(request)
  File "/Applications/anaconda3/lib/python3.6/site-packages/django/core/handlers/base.py", line 179, in _get_response
    response = wrapped_callback(request, *callback_args, **callback_kwargs)
  File "/Users/fengdong/PycharmProjects/flowpredict000/flowpredict/warn_relaction_interface/view.py", line 102, in get_resu_process
    req_para = json.loads(req.body)
  File "/Applications/anaconda3/lib/python3.6/json/__init__.py", line 354, in loads
    return _default_decoder.decode(s)
  File "/Applications/anaconda3/lib/python3.6/json/decoder.py", line 339, in decode
    obj, end = self.raw_decode(s, idx=_w(s, 0).end())
  File "/Applications/anaconda3/lib/python3.6/json/decoder.py", line 357, in raw_decode
    raise JSONDecodeError("Expecting value", s, err.value) from None
json.decoder.JSONDecodeError: Expecting value: line 1 column 1 (char 0)
[2020-09-16 16:26:18,267] [basehttp.py:157] [basehttp:log_message] [ERROR]- "POST /get_resu_process?work_id=48aaa2e8deaa3d4f27142445bfc36cd1 HTTP/1.1" 500 145
[2020-09-16 16:26:36,223] [log.py:230] [log:log_response] [ERROR]- Internal Server Error: /get_resu_process
Traceback (most recent call last):
  File "/Applications/anaconda3/lib/python3.6/site-packages/django/core/handlers/exception.py", line 47, in inner
    response = get_response(request)
  File "/Applications/anaconda3/lib/python3.6/site-packages/django/core/handlers/base.py", line 179, in _get_response
    response = wrapped_callback(request, *callback_args, **callback_kwargs)
  File "/Users/fengdong/PycharmProjects/flowpredict000/flowpredict/warn_relaction_interface/view.py", line 102, in get_resu_process
    req_para = json.loads(req.body)
  File "/Applications/anaconda3/lib/python3.6/json/__init__.py", line 354, in loads
    return _default_decoder.decode(s)
  File "/Applications/anaconda3/lib/python3.6/json/decoder.py", line 339, in decode
    obj, end = self.raw_decode(s, idx=_w(s, 0).end())
  File "/Applications/anaconda3/lib/python3.6/json/decoder.py", line 357, in raw_decode
    raise JSONDecodeError("Expecting value", s, err.value) from None
json.decoder.JSONDecodeError: Expecting value: line 1 column 1 (char 0)
[2020-09-16 16:26:36,224] [basehttp.py:157] [basehttp:log_message] [ERROR]- "POST /get_resu_process?work_id=48aaa2e8deaa3d4f27142445bfc36cd1 HTTP/1.1" 500 145
[2020-09-16 16:27:22,314] [autoreload.py:236] [autoreload:trigger_reload] [INFO]- /Users/fengdong/PycharmProjects/flowpredict000/flowpredict/warn_relaction_interface/view.py changed, reloading.
[2020-09-16 16:27:22,919] [autoreload.py:612] [autoreload:run_with_reloader] [INFO]- Watching for file changes with StatReloader
[2020-09-16 16:27:41,109] [log.py:230] [log:log_response] [ERROR]- Internal Server Error: /get_resu_process
Traceback (most recent call last):
  File "/Applications/anaconda3/lib/python3.6/site-packages/django/core/handlers/exception.py", line 47, in inner
    response = get_response(request)
  File "/Applications/anaconda3/lib/python3.6/site-packages/django/core/handlers/base.py", line 179, in _get_response
    response = wrapped_callback(request, *callback_args, **callback_kwargs)
  File "/Users/fengdong/PycharmProjects/flowpredict000/flowpredict/warn_relaction_interface/view.py", line 102, in get_resu_process
    req_para = json.loads(req.body)
  File "/Applications/anaconda3/lib/python3.6/json/__init__.py", line 354, in loads
    return _default_decoder.decode(s)
  File "/Applications/anaconda3/lib/python3.6/json/decoder.py", line 339, in decode
    obj, end = self.raw_decode(s, idx=_w(s, 0).end())
  File "/Applications/anaconda3/lib/python3.6/json/decoder.py", line 357, in raw_decode
    raise JSONDecodeError("Expecting value", s, err.value) from None
json.decoder.JSONDecodeError: Expecting value: line 1 column 1 (char 0)
[2020-09-16 16:27:41,119] [basehttp.py:157] [basehttp:log_message] [ERROR]- "POST /get_resu_process?work_id=48aaa2e8deaa3d4f27142445bfc36cd1 HTTP/1.1" 500 145
[2020-09-16 16:28:26,195] [log.py:230] [log:log_response] [ERROR]- Internal Server Error: /get_resu_process
Traceback (most recent call last):
  File "/Applications/anaconda3/lib/python3.6/site-packages/django/core/handlers/exception.py", line 47, in inner
    response = get_response(request)
  File "/Applications/anaconda3/lib/python3.6/site-packages/django/core/handlers/base.py", line 179, in _get_response
    response = wrapped_callback(request, *callback_args, **callback_kwargs)
  File "/Users/fengdong/PycharmProjects/flowpredict000/flowpredict/warn_relaction_interface/view.py", line 102, in get_resu_process
    req_para = json.loads(req.body)
  File "/Applications/anaconda3/lib/python3.6/json/__init__.py", line 354, in loads
    return _default_decoder.decode(s)
  File "/Applications/anaconda3/lib/python3.6/json/decoder.py", line 339, in decode
    obj, end = self.raw_decode(s, idx=_w(s, 0).end())
  File "/Applications/anaconda3/lib/python3.6/json/decoder.py", line 357, in raw_decode
    raise JSONDecodeError("Expecting value", s, err.value) from None
json.decoder.JSONDecodeError: Expecting value: line 1 column 1 (char 0)
[2020-09-16 16:28:26,195] [basehttp.py:157] [basehttp:log_message] [ERROR]- "POST /get_resu_process?warn_file=uploads/67c35597-7cc2-45ab-8fe5-64ba13f09fe0.csv HTTP/1.1" 500 145
[2020-09-16 16:28:37,929] [basehttp.py:157] [basehttp:log_message] [INFO]- "POST /upload_file?warn_file=uploads/67c35597-7cc2-45ab-8fe5-64ba13f09fe0.csv HTTP/1.1" 200 128
[2020-09-16 16:28:52,525] [basehttp.py:157] [basehttp:log_message] [INFO]- "POST /upload_file?warn_file=uploads/67c35597-7cc2-45ab-8fe5-64ba13f09fe0.csv HTTP/1.1" 200 128
[2020-09-16 16:31:21,892] [autoreload.py:612] [autoreload:run_with_reloader] [INFO]- Watching for file changes with StatReloader
[2020-09-16 16:31:29,432] [basehttp.py:157] [basehttp:log_message] [INFO]- "POST /upload_file?warn_file=uploads/67c35597-7cc2-45ab-8fe5-64ba13f09fe0.csv HTTP/1.1" 200 128
[2020-09-16 16:31:33,234] [basehttp.py:157] [basehttp:log_message] [INFO]- "POST /upload_file?warn_file=uploads/67c35597-7cc2-45ab-8fe5-64ba13f09fe0.csv HTTP/1.1" 200 128
[2020-09-16 16:33:55,044] [view.py:80] [view:warn_realtion] [ERROR]- [75250f844775990bee82c3a26cca1a35]:Expecting value: line 1 column 1 (char 0)
[2020-09-16 16:33:55,045] [basehttp.py:157] [basehttp:log_message] [INFO]- "POST /get_flow?warn_data_url=http://172.16.229.130:8111/static/upload/lteFlowOfCity5Min_anshun_guanling.csv HTTP/1.1" 200 66
[2020-09-16 16:34:27,838] [view.py:80] [view:warn_realtion] [ERROR]- [97407eba82d2bf7ddf2622bc9ff8b004]:Expecting value: line 1 column 1 (char 0)
[2020-09-16 16:34:27,838] [basehttp.py:157] [basehttp:log_message] [INFO]- "POST /get_flow?warn_data_url=http://172.16.229.130:8111/static/upload/lteFlowOfCity5Min_anshun_guanling.csv HTTP/1.1" 200 66
[2020-09-16 16:34:35,660] [view.py:80] [view:warn_realtion] [ERROR]- [6451fa5585462cafdc1fff842555ec27]:Expecting value: line 1 column 1 (char 0)
[2020-09-16 16:34:35,661] [basehttp.py:157] [basehttp:log_message] [INFO]- "POST /get_flow?warn_data_url=static/upload/lteFlowOfCity5Min_anshun_guanling.csv HTTP/1.1" 200 66
[2020-09-16 16:35:13,044] [view.py:80] [view:warn_realtion] [ERROR]- [f47440844da5dab411aae12c386b0505]:Expecting value: line 1 column 1 (char 0)
[2020-09-16 16:35:13,045] [basehttp.py:157] [basehttp:log_message] [INFO]- "POST /get_flow?warn_data_url=static/upload/lteFlowOfCity5Min_anshun_guanling.csv HTTP/1.1" 200 66
[2020-09-16 16:35:49,255] [autoreload.py:236] [autoreload:trigger_reload] [INFO]- /Users/fengdong/PycharmProjects/flowpredict000/flowpredict/warn_relaction_interface/view.py changed, reloading.
[2020-09-16 16:35:49,944] [autoreload.py:612] [autoreload:run_with_reloader] [INFO]- Watching for file changes with StatReloader
[2020-09-16 16:36:19,151] [view.py:79] [view:warn_realtion] [ERROR]- [80bd3445a09120f3398d0e6ab37d359d]:Expecting value: line 1 column 1 (char 0)
[2020-09-16 16:36:19,152] [basehttp.py:157] [basehttp:log_message] [INFO]- "POST /get_flow HTTP/1.1" 200 66
[2020-09-16 16:36:28,218] [view.py:79] [view:warn_realtion] [ERROR]- [851af847000d1c36f678ea0606dfd1ce]:Expecting value: line 1 column 1 (char 0)
[2020-09-16 16:36:28,219] [basehttp.py:157] [basehttp:log_message] [INFO]- "POST /get_flow HTTP/1.1" 200 66
[2020-09-16 16:39:23,125] [view.py:79] [view:warn_realtion] [ERROR]- [b5e12f33350faa9eaa424506ef06bce9]:Expecting value: line 1 column 1 (char 0)
[2020-09-16 16:39:23,126] [basehttp.py:157] [basehttp:log_message] [INFO]- "POST /get_flow HTTP/1.1" 200 66
[2020-09-16 16:39:34,585] [view.py:79] [view:warn_realtion] [ERROR]- [02195c3d2309cd2e0c5df2bdcd5ecc64]:Expecting value: line 1 column 1 (char 0)
[2020-09-16 16:39:34,586] [basehttp.py:157] [basehttp:log_message] [INFO]- "POST /get_flow HTTP/1.1" 200 66
[2020-09-16 16:40:03,526] [view.py:79] [view:warn_realtion] [ERROR]- [d361bcbf80548886ff518609c8680215]:Expecting value: line 1 column 1 (char 0)
[2020-09-16 16:40:03,527] [basehttp.py:157] [basehttp:log_message] [INFO]- "POST /get_flow HTTP/1.1" 200 66
[2020-09-16 16:40:03,719] [autoreload.py:236] [autoreload:trigger_reload] [INFO]- /Users/fengdong/PycharmProjects/flowpredict000/flowpredict/warn_relaction_interface/view.py changed, reloading.
[2020-09-16 16:40:04,621] [autoreload.py:612] [autoreload:run_with_reloader] [INFO]- Watching for file changes with StatReloader
[2020-09-16 16:40:12,166] [view.py:79] [view:warn_realtion] [ERROR]- [91ce2548b95ac04321facbc192e9dacf]:Expecting value: line 1 column 1 (char 0)
[2020-09-16 16:40:12,168] [basehttp.py:157] [basehttp:log_message] [INFO]- "POST /get_flow HTTP/1.1" 200 66
[2020-09-16 16:40:45,465] [view.py:79] [view:warn_realtion] [ERROR]- [2146f6e35bf48a2622fa304d14ad3816]:Expecting value: line 1 column 1 (char 0)
[2020-09-16 16:40:45,466] [basehttp.py:157] [basehttp:log_message] [INFO]- "POST /get_flow HTTP/1.1" 200 66
[2020-09-16 16:40:45,846] [autoreload.py:236] [autoreload:trigger_reload] [INFO]- /Users/fengdong/PycharmProjects/flowpredict000/flowpredict/warn_relaction_interface/view.py changed, reloading.
[2020-09-16 16:40:46,662] [autoreload.py:612] [autoreload:run_with_reloader] [INFO]- Watching for file changes with StatReloader
[2020-09-16 16:41:00,163] [view.py:80] [view:warn_realtion] [ERROR]- [538ac7afb31f8c86e1972dfd04b7eb5c]:Expecting value: line 1 column 1 (char 0)
[2020-09-16 16:41:00,164] [basehttp.py:157] [basehttp:log_message] [INFO]- "POST /get_flow HTTP/1.1" 200 66
[2020-09-16 16:44:19,902] [autoreload.py:236] [autoreload:trigger_reload] [INFO]- /Users/fengdong/PycharmProjects/flowpredict000/flowpredict/warn_relaction_interface/view.py changed, reloading.
[2020-09-16 16:44:20,756] [autoreload.py:612] [autoreload:run_with_reloader] [INFO]- Watching for file changes with StatReloader
[2020-09-16 16:44:27,923] [view.py:80] [view:warn_realtion] [ERROR]- [777acafdbfa4c2cebfc8e64b518bcc70]:Expecting value: line 1 column 1 (char 0)
[2020-09-16 16:44:27,924] [basehttp.py:157] [basehttp:log_message] [INFO]- "POST /get_flow HTTP/1.1" 200 66
[2020-09-16 16:46:16,953] [autoreload.py:236] [autoreload:trigger_reload] [INFO]- /Users/fengdong/PycharmProjects/flowpredict000/flowpredict/warn_relaction_interface/view.py changed, reloading.
[2020-09-16 16:46:17,934] [autoreload.py:612] [autoreload:run_with_reloader] [INFO]- Watching for file changes with StatReloader
[2020-09-16 16:46:21,027] [view.py:81] [view:warn_realtion] [ERROR]- [f8ec8ddb5b813efbd35830d061b0291b]:Expecting value: line 1 column 1 (char 0)
[2020-09-16 16:46:21,028] [basehttp.py:157] [basehttp:log_message] [INFO]- "POST /get_flow HTTP/1.1" 200 66
[2020-09-16 16:46:30,665] [view.py:81] [view:warn_realtion] [ERROR]- [77642a03f534546e8b13042d0705ac51]:Expecting value: line 1 column 1 (char 0)
[2020-09-16 16:46:30,666] [basehttp.py:157] [basehttp:log_message] [INFO]- "POST /get_flow HTTP/1.1" 200 66
[2020-09-16 16:47:58,914] [autoreload.py:236] [autoreload:trigger_reload] [INFO]- /Users/fengdong/PycharmProjects/flowpredict000/flowpredict/warn_relaction_interface/view.py changed, reloading.
[2020-09-16 16:47:59,804] [autoreload.py:612] [autoreload:run_with_reloader] [INFO]- Watching for file changes with StatReloader
[2020-09-16 16:48:49,617] [autoreload.py:236] [autoreload:trigger_reload] [INFO]- /Users/fengdong/PycharmProjects/flowpredict000/flowpredict/warn_relaction_interface/view.py changed, reloading.
[2020-09-16 16:48:50,531] [autoreload.py:612] [autoreload:run_with_reloader] [INFO]- Watching for file changes with StatReloader
[2020-09-16 16:48:55,689] [view.py:83] [view:warn_realtion] [ERROR]- [d53570fa9c51eebccc359b33ec89e61b]:Expecting value: line 1 column 1 (char 0)
[2020-09-16 16:48:55,691] [basehttp.py:157] [basehttp:log_message] [INFO]- "POST /get_flow HTTP/1.1" 200 66
[2020-09-16 16:49:26,589] [autoreload.py:236] [autoreload:trigger_reload] [INFO]- /Users/fengdong/PycharmProjects/flowpredict000/flowpredict/warn_relaction_interface/view.py changed, reloading.
[2020-09-16 16:49:27,218] [autoreload.py:612] [autoreload:run_with_reloader] [INFO]- Watching for file changes with StatReloader
[2020-09-16 16:49:29,352] [view.py:84] [view:warn_realtion] [ERROR]- [0abdbfa24808572002186d4ec92fe225]:Expecting value: line 1 column 1 (char 0)
[2020-09-16 16:49:29,353] [basehttp.py:157] [basehttp:log_message] [INFO]- "POST /get_flow HTTP/1.1" 200 66
[2020-09-16 23:35:25,928] [autoreload.py:612] [autoreload:run_with_reloader] [INFO]- Watching for file changes with StatReloader
[2020-09-16 23:35:35,549] [view.py:84] [view:warn_realtion] [ERROR]- [16bb956c663767f9aeeb4e796f6908f6]:Expecting value: line 1 column 1 (char 0)
[2020-09-16 23:35:35,551] [basehttp.py:157] [basehttp:log_message] [INFO]- "POST /get_flow?warn_data_url=static/upload/lteFlowOfCity5Min_anshun_guanling.csv HTTP/1.1" 200 66
[2020-09-16 23:35:36,686] [view.py:84] [view:warn_realtion] [ERROR]- [9ac3fcaa01a079ea15df63b470e384a2]:Expecting value: line 1 column 1 (char 0)
[2020-09-16 23:35:36,687] [basehttp.py:157] [basehttp:log_message] [INFO]- "POST /get_flow?warn_data_url=static/upload/lteFlowOfCity5Min_anshun_guanling.csv HTTP/1.1" 200 66
[2020-09-16 23:35:37,315] [view.py:84] [view:warn_realtion] [ERROR]- [373766b219db7ea270dab474528745b1]:Expecting value: line 1 column 1 (char 0)
[2020-09-16 23:35:37,316] [basehttp.py:157] [basehttp:log_message] [INFO]- "POST /get_flow?warn_data_url=static/upload/lteFlowOfCity5Min_anshun_guanling.csv HTTP/1.1" 200 66
[2020-09-16 23:35:38,743] [view.py:84] [view:warn_realtion] [ERROR]- [1d766a3b6a15e68858702ae0f97cd34b]:Expecting value: line 1 column 1 (char 0)
[2020-09-16 23:35:38,743] [basehttp.py:157] [basehttp:log_message] [INFO]- "POST /get_flow?warn_data_url=static/upload/lteFlowOfCity5Min_anshun_guanling.csv HTTP/1.1" 200 66
[2020-09-16 23:35:43,965] [basehttp.py:157] [basehttp:log_message] [INFO]- "POST /?warn_data_url=static/upload/lteFlowOfCity5Min_anshun_guanling.csv HTTP/1.1" 200 67
[2020-09-16 23:35:45,216] [basehttp.py:157] [basehttp:log_message] [INFO]- "POST /?warn_data_url=static/upload/lteFlowOfCity5Min_anshun_guanling.csv HTTP/1.1" 200 67
[2020-09-16 23:35:46,895] [basehttp.py:157] [basehttp:log_message] [INFO]- "POST /?warn_data_url=static/upload/lteFlowOfCity5Min_anshun_guanling.csv HTTP/1.1" 200 67
[2020-09-16 23:38:54,774] [view.py:84] [view:warn_realtion] [ERROR]- [f928f2368c02147db421123f24a6bc31]:Expecting value: line 1 column 1 (char 0)
[2020-09-16 23:38:54,781] [basehttp.py:157] [basehttp:log_message] [INFO]- "POST /get_flow?warn_data_url=static/upload/lteFlowOfCity5Min_anshun_guanling.csv HTTP/1.1" 200 66
[2020-09-16 23:38:59,542] [view.py:84] [view:warn_realtion] [ERROR]- [8f14f1bd3c1bfab918414bb20857d79b]:Expecting value: line 1 column 1 (char 0)
[2020-09-16 23:38:59,543] [basehttp.py:157] [basehttp:log_message] [INFO]- "POST /get_flow?warn_data_url=static/upload/lteFlowOfCity5Min_anshun_guanling.csv HTTP/1.1" 200 66
[2020-09-16 23:39:16,679] [autoreload.py:236] [autoreload:trigger_reload] [INFO]- /Users/fengdong/PycharmProjects/flowpredict000/flowpredict/warn_relaction_interface/view.py changed, reloading.
[2020-09-16 23:39:17,632] [autoreload.py:612] [autoreload:run_with_reloader] [INFO]- Watching for file changes with StatReloader
[2020-09-16 23:39:22,605] [view.py:84] [view:warn_realtion] [ERROR]- [e1ecc5c083e45ffc9c8d4ea08734060b]:Expecting value: line 1 column 1 (char 0)
[2020-09-16 23:39:22,607] [basehttp.py:157] [basehttp:log_message] [INFO]- "POST /get_flow?warn_data_url=static/upload/lteFlowOfCity5Min_anshun_guanling.csv HTTP/1.1" 200 66
[2020-09-16 23:48:10,428] [log.py:230] [log:log_response] [WARNING]- Not Found: /static/upload
[2020-09-16 23:48:10,428] [basehttp.py:157] [basehttp:log_message] [WARNING]- "POST /static/upload?warn_data_url=static/upload/lteFlowOfCity5Min_anshun_guanling.csv HTTP/1.1" 404 179
[2020-09-16 23:52:02,391] [log.py:230] [log:log_response] [ERROR]- Internal Server Error: /get_resu_process
Traceback (most recent call last):
  File "/Applications/anaconda3/lib/python3.6/site-packages/django/core/handlers/exception.py", line 47, in inner
    response = get_response(request)
  File "/Applications/anaconda3/lib/python3.6/site-packages/django/core/handlers/base.py", line 179, in _get_response
    response = wrapped_callback(request, *callback_args, **callback_kwargs)
  File "/Users/fengdong/PycharmProjects/flowpredict000/flowpredict/warn_relaction_interface/view.py", line 106, in get_resu_process
    req_para = json.loads(req.body)
  File "/Applications/anaconda3/lib/python3.6/json/__init__.py", line 354, in loads
    return _default_decoder.decode(s)
  File "/Applications/anaconda3/lib/python3.6/json/decoder.py", line 339, in decode
    obj, end = self.raw_decode(s, idx=_w(s, 0).end())
  File "/Applications/anaconda3/lib/python3.6/json/decoder.py", line 357, in raw_decode
    raise JSONDecodeError("Expecting value", s, err.value) from None
json.decoder.JSONDecodeError: Expecting value: line 1 column 1 (char 0)
[2020-09-16 23:52:02,404] [basehttp.py:157] [basehttp:log_message] [ERROR]- "POST /get_resu_process?work_id=ad854c895401a84cfcb32b1d46922a0b HTTP/1.1" 500 145
[2020-09-16 23:52:07,556] [log.py:230] [log:log_response] [ERROR]- Internal Server Error: /get_resu_process
Traceback (most recent call last):
  File "/Applications/anaconda3/lib/python3.6/site-packages/django/core/handlers/exception.py", line 47, in inner
    response = get_response(request)
  File "/Applications/anaconda3/lib/python3.6/site-packages/django/core/handlers/base.py", line 179, in _get_response
    response = wrapped_callback(request, *callback_args, **callback_kwargs)
  File "/Users/fengdong/PycharmProjects/flowpredict000/flowpredict/warn_relaction_interface/view.py", line 106, in get_resu_process
    req_para = json.loads(req.body)
  File "/Applications/anaconda3/lib/python3.6/json/__init__.py", line 354, in loads
    return _default_decoder.decode(s)
  File "/Applications/anaconda3/lib/python3.6/json/decoder.py", line 339, in decode
    obj, end = self.raw_decode(s, idx=_w(s, 0).end())
  File "/Applications/anaconda3/lib/python3.6/json/decoder.py", line 357, in raw_decode
    raise JSONDecodeError("Expecting value", s, err.value) from None
json.decoder.JSONDecodeError: Expecting value: line 1 column 1 (char 0)
[2020-09-16 23:52:07,557] [basehttp.py:157] [basehttp:log_message] [ERROR]- "POST /get_resu_process?work_id=ad854c895401a84cfcb32b1d46922a0b HTTP/1.1" 500 145
[2020-09-16 23:52:08,716] [log.py:230] [log:log_response] [ERROR]- Internal Server Error: /get_resu_process
Traceback (most recent call last):
  File "/Applications/anaconda3/lib/python3.6/site-packages/django/core/handlers/exception.py", line 47, in inner
    response = get_response(request)
  File "/Applications/anaconda3/lib/python3.6/site-packages/django/core/handlers/base.py", line 179, in _get_response
    response = wrapped_callback(request, *callback_args, **callback_kwargs)
  File "/Users/fengdong/PycharmProjects/flowpredict000/flowpredict/warn_relaction_interface/view.py", line 106, in get_resu_process
    req_para = json.loads(req.body)
  File "/Applications/anaconda3/lib/python3.6/json/__init__.py", line 354, in loads
    return _default_decoder.decode(s)
  File "/Applications/anaconda3/lib/python3.6/json/decoder.py", line 339, in decode
    obj, end = self.raw_decode(s, idx=_w(s, 0).end())
  File "/Applications/anaconda3/lib/python3.6/json/decoder.py", line 357, in raw_decode
    raise JSONDecodeError("Expecting value", s, err.value) from None
json.decoder.JSONDecodeError: Expecting value: line 1 column 1 (char 0)
[2020-09-16 23:52:08,716] [basehttp.py:157] [basehttp:log_message] [ERROR]- "POST /get_resu_process?work_id=ad854c895401a84cfcb32b1d46922a0b HTTP/1.1" 500 145
[2020-09-16 23:52:09,409] [log.py:230] [log:log_response] [ERROR]- Internal Server Error: /get_resu_process
Traceback (most recent call last):
  File "/Applications/anaconda3/lib/python3.6/site-packages/django/core/handlers/exception.py", line 47, in inner
    response = get_response(request)
  File "/Applications/anaconda3/lib/python3.6/site-packages/django/core/handlers/base.py", line 179, in _get_response
    response = wrapped_callback(request, *callback_args, **callback_kwargs)
  File "/Users/fengdong/PycharmProjects/flowpredict000/flowpredict/warn_relaction_interface/view.py", line 106, in get_resu_process
    req_para = json.loads(req.body)
  File "/Applications/anaconda3/lib/python3.6/json/__init__.py", line 354, in loads
    return _default_decoder.decode(s)
  File "/Applications/anaconda3/lib/python3.6/json/decoder.py", line 339, in decode
    obj, end = self.raw_decode(s, idx=_w(s, 0).end())
  File "/Applications/anaconda3/lib/python3.6/json/decoder.py", line 357, in raw_decode
    raise JSONDecodeError("Expecting value", s, err.value) from None
json.decoder.JSONDecodeError: Expecting value: line 1 column 1 (char 0)
[2020-09-16 23:52:09,410] [basehttp.py:157] [basehttp:log_message] [ERROR]- "POST /get_resu_process?work_id=ad854c895401a84cfcb32b1d46922a0b HTTP/1.1" 500 145
[2020-09-16 23:52:10,044] [log.py:230] [log:log_response] [ERROR]- Internal Server Error: /get_resu_process
Traceback (most recent call last):
  File "/Applications/anaconda3/lib/python3.6/site-packages/django/core/handlers/exception.py", line 47, in inner
    response = get_response(request)
  File "/Applications/anaconda3/lib/python3.6/site-packages/django/core/handlers/base.py", line 179, in _get_response
    response = wrapped_callback(request, *callback_args, **callback_kwargs)
  File "/Users/fengdong/PycharmProjects/flowpredict000/flowpredict/warn_relaction_interface/view.py", line 106, in get_resu_process
    req_para = json.loads(req.body)
  File "/Applications/anaconda3/lib/python3.6/json/__init__.py", line 354, in loads
    return _default_decoder.decode(s)
  File "/Applications/anaconda3/lib/python3.6/json/decoder.py", line 339, in decode
    obj, end = self.raw_decode(s, idx=_w(s, 0).end())
  File "/Applications/anaconda3/lib/python3.6/json/decoder.py", line 357, in raw_decode
    raise JSONDecodeError("Expecting value", s, err.value) from None
json.decoder.JSONDecodeError: Expecting value: line 1 column 1 (char 0)
[2020-09-16 23:52:10,045] [basehttp.py:157] [basehttp:log_message] [ERROR]- "POST /get_resu_process?work_id=ad854c895401a84cfcb32b1d46922a0b HTTP/1.1" 500 145
[2020-09-16 23:52:10,644] [log.py:230] [log:log_response] [ERROR]- Internal Server Error: /get_resu_process
Traceback (most recent call last):
  File "/Applications/anaconda3/lib/python3.6/site-packages/django/core/handlers/exception.py", line 47, in inner
    response = get_response(request)
  File "/Applications/anaconda3/lib/python3.6/site-packages/django/core/handlers/base.py", line 179, in _get_response
    response = wrapped_callback(request, *callback_args, **callback_kwargs)
  File "/Users/fengdong/PycharmProjects/flowpredict000/flowpredict/warn_relaction_interface/view.py", line 106, in get_resu_process
    req_para = json.loads(req.body)
  File "/Applications/anaconda3/lib/python3.6/json/__init__.py", line 354, in loads
    return _default_decoder.decode(s)
  File "/Applications/anaconda3/lib/python3.6/json/decoder.py", line 339, in decode
    obj, end = self.raw_decode(s, idx=_w(s, 0).end())
  File "/Applications/anaconda3/lib/python3.6/json/decoder.py", line 357, in raw_decode
    raise JSONDecodeError("Expecting value", s, err.value) from None
json.decoder.JSONDecodeError: Expecting value: line 1 column 1 (char 0)
[2020-09-16 23:52:10,645] [basehttp.py:157] [basehttp:log_message] [ERROR]- "POST /get_resu_process?work_id=ad854c895401a84cfcb32b1d46922a0b HTTP/1.1" 500 145
[2020-09-16 23:52:11,050] [log.py:230] [log:log_response] [ERROR]- Internal Server Error: /get_resu_process
Traceback (most recent call last):
  File "/Applications/anaconda3/lib/python3.6/site-packages/django/core/handlers/exception.py", line 47, in inner
    response = get_response(request)
  File "/Applications/anaconda3/lib/python3.6/site-packages/django/core/handlers/base.py", line 179, in _get_response
    response = wrapped_callback(request, *callback_args, **callback_kwargs)
  File "/Users/fengdong/PycharmProjects/flowpredict000/flowpredict/warn_relaction_interface/view.py", line 106, in get_resu_process
    req_para = json.loads(req.body)
  File "/Applications/anaconda3/lib/python3.6/json/__init__.py", line 354, in loads
    return _default_decoder.decode(s)
  File "/Applications/anaconda3/lib/python3.6/json/decoder.py", line 339, in decode
    obj, end = self.raw_decode(s, idx=_w(s, 0).end())
  File "/Applications/anaconda3/lib/python3.6/json/decoder.py", line 357, in raw_decode
    raise JSONDecodeError("Expecting value", s, err.value) from None
json.decoder.JSONDecodeError: Expecting value: line 1 column 1 (char 0)
[2020-09-16 23:52:11,051] [basehttp.py:157] [basehttp:log_message] [ERROR]- "POST /get_resu_process?work_id=ad854c895401a84cfcb32b1d46922a0b HTTP/1.1" 500 145
[2020-09-16 23:52:31,678] [autoreload.py:612] [autoreload:run_with_reloader] [INFO]- Watching for file changes with StatReloader
[2020-09-16 23:52:40,198] [log.py:230] [log:log_response] [ERROR]- Internal Server Error: /get_resu_process
Traceback (most recent call last):
  File "/Applications/anaconda3/lib/python3.6/site-packages/django/core/handlers/exception.py", line 47, in inner
    response = get_response(request)
  File "/Applications/anaconda3/lib/python3.6/site-packages/django/core/handlers/base.py", line 179, in _get_response
    response = wrapped_callback(request, *callback_args, **callback_kwargs)
  File "/Users/fengdong/PycharmProjects/flowpredict000/flowpredict/warn_relaction_interface/view.py", line 106, in get_resu_process
    req_para = json.loads(req.body)
  File "/Applications/anaconda3/lib/python3.6/json/__init__.py", line 354, in loads
    return _default_decoder.decode(s)
  File "/Applications/anaconda3/lib/python3.6/json/decoder.py", line 339, in decode
    obj, end = self.raw_decode(s, idx=_w(s, 0).end())
  File "/Applications/anaconda3/lib/python3.6/json/decoder.py", line 357, in raw_decode
    raise JSONDecodeError("Expecting value", s, err.value) from None
json.decoder.JSONDecodeError: Expecting value: line 1 column 1 (char 0)
[2020-09-16 23:52:40,219] [basehttp.py:157] [basehttp:log_message] [ERROR]- "POST /get_resu_process?work_id=ad854c895401a84cfcb32b1d46922a0b HTTP/1.1" 500 145
[2020-09-16 23:53:34,264] [log.py:230] [log:log_response] [ERROR]- Internal Server Error: /get_resu_process
Traceback (most recent call last):
  File "/Applications/anaconda3/lib/python3.6/site-packages/django/core/handlers/exception.py", line 47, in inner
    response = get_response(request)
  File "/Applications/anaconda3/lib/python3.6/site-packages/django/core/handlers/base.py", line 179, in _get_response
    response = wrapped_callback(request, *callback_args, **callback_kwargs)
  File "/Users/fengdong/PycharmProjects/flowpredict000/flowpredict/warn_relaction_interface/view.py", line 106, in get_resu_process
    req_para = json.loads(req.body)
  File "/Applications/anaconda3/lib/python3.6/json/__init__.py", line 354, in loads
    return _default_decoder.decode(s)
  File "/Applications/anaconda3/lib/python3.6/json/decoder.py", line 339, in decode
    obj, end = self.raw_decode(s, idx=_w(s, 0).end())
  File "/Applications/anaconda3/lib/python3.6/json/decoder.py", line 357, in raw_decode
    raise JSONDecodeError("Expecting value", s, err.value) from None
json.decoder.JSONDecodeError: Expecting value: line 1 column 1 (char 0)
[2020-09-16 23:53:34,265] [basehttp.py:157] [basehttp:log_message] [ERROR]- "POST /get_resu_process HTTP/1.1" 500 145
[2020-09-16 23:53:42,814] [log.py:230] [log:log_response] [ERROR]- Internal Server Error: /get_resu_process
Traceback (most recent call last):
  File "/Applications/anaconda3/lib/python3.6/site-packages/django/core/handlers/exception.py", line 47, in inner
    response = get_response(request)
  File "/Applications/anaconda3/lib/python3.6/site-packages/django/core/handlers/base.py", line 179, in _get_response
    response = wrapped_callback(request, *callback_args, **callback_kwargs)
  File "/Users/fengdong/PycharmProjects/flowpredict000/flowpredict/warn_relaction_interface/view.py", line 106, in get_resu_process
    req_para = json.loads(req.body)
  File "/Applications/anaconda3/lib/python3.6/json/__init__.py", line 354, in loads
    return _default_decoder.decode(s)
  File "/Applications/anaconda3/lib/python3.6/json/decoder.py", line 339, in decode
    obj, end = self.raw_decode(s, idx=_w(s, 0).end())
  File "/Applications/anaconda3/lib/python3.6/json/decoder.py", line 357, in raw_decode
    raise JSONDecodeError("Expecting value", s, err.value) from None
json.decoder.JSONDecodeError: Expecting value: line 1 column 1 (char 0)
[2020-09-16 23:53:42,815] [basehttp.py:157] [basehttp:log_message] [ERROR]- "POST /get_resu_process HTTP/1.1" 500 145
[2020-09-16 23:55:43,202] [autoreload.py:236] [autoreload:trigger_reload] [INFO]- /Users/fengdong/PycharmProjects/flowpredict000/flowpredict/warn_relaction_interface/view.py changed, reloading.
[2020-09-16 23:55:44,164] [autoreload.py:612] [autoreload:run_with_reloader] [INFO]- Watching for file changes with StatReloader
[2020-09-16 23:56:09,965] [log.py:230] [log:log_response] [ERROR]- Internal Server Error: /get_resu_process
Traceback (most recent call last):
  File "/Applications/anaconda3/lib/python3.6/site-packages/django/core/handlers/exception.py", line 47, in inner
    response = get_response(request)
  File "/Applications/anaconda3/lib/python3.6/site-packages/django/core/handlers/base.py", line 179, in _get_response
    response = wrapped_callback(request, *callback_args, **callback_kwargs)
  File "/Users/fengdong/PycharmProjects/flowpredict000/flowpredict/warn_relaction_interface/view.py", line 106, in get_resu_process
    req_para = json.dumps(req.body)
  File "/Applications/anaconda3/lib/python3.6/json/__init__.py", line 231, in dumps
    return _default_encoder.encode(obj)
  File "/Applications/anaconda3/lib/python3.6/json/encoder.py", line 199, in encode
    chunks = self.iterencode(o, _one_shot=True)
  File "/Applications/anaconda3/lib/python3.6/json/encoder.py", line 257, in iterencode
    return _iterencode(o, 0)
  File "/Applications/anaconda3/lib/python3.6/json/encoder.py", line 180, in default
    o.__class__.__name__)
TypeError: Object of type 'bytes' is not JSON serializable
[2020-09-16 23:56:09,971] [basehttp.py:157] [basehttp:log_message] [ERROR]- "POST /get_resu_process HTTP/1.1" 500 145
[2020-09-16 23:57:39,204] [autoreload.py:236] [autoreload:trigger_reload] [INFO]- /Users/fengdong/PycharmProjects/flowpredict000/flowpredict/warn_relaction_interface/view.py changed, reloading.
[2020-09-16 23:57:40,023] [autoreload.py:612] [autoreload:run_with_reloader] [INFO]- Watching for file changes with StatReloader
[2020-09-16 23:57:46,272] [log.py:230] [log:log_response] [ERROR]- Internal Server Error: /get_resu_process
Traceback (most recent call last):
  File "/Applications/anaconda3/lib/python3.6/site-packages/django/core/handlers/exception.py", line 47, in inner
    response = get_response(request)
  File "/Applications/anaconda3/lib/python3.6/site-packages/django/core/handlers/base.py", line 179, in _get_response
    response = wrapped_callback(request, *callback_args, **callback_kwargs)
  File "/Users/fengdong/PycharmProjects/flowpredict000/flowpredict/warn_relaction_interface/view.py", line 106, in get_resu_process
    req_para = json.load(req.body)
  File "/Applications/anaconda3/lib/python3.6/json/__init__.py", line 296, in load
    return loads(fp.read(),
AttributeError: 'bytes' object has no attribute 'read'
[2020-09-16 23:57:46,278] [basehttp.py:157] [basehttp:log_message] [ERROR]- "POST /get_resu_process HTTP/1.1" 500 145
[2020-09-16 23:58:26,695] [autoreload.py:236] [autoreload:trigger_reload] [INFO]- /Users/fengdong/PycharmProjects/flowpredict000/flowpredict/warn_relaction_interface/view.py changed, reloading.
[2020-09-16 23:58:27,487] [autoreload.py:612] [autoreload:run_with_reloader] [INFO]- Watching for file changes with StatReloader
[2020-09-17 00:11:38,419] [autoreload.py:236] [autoreload:trigger_reload] [INFO]- /Users/fengdong/PycharmProjects/flowpredict000/flowpredict/warn_relaction_interface/view.py changed, reloading.
